Workbook

Sheet 入出金合計表 【第18期2026年6月～】 
B1: 2025年5月末残 | C1: ='入出金合計表 【第17期2025年6月～】'!C391 -> -13412076
C2: ２０２6年６月‐２０２7年５月残高
C3: 残高日次 | D3: 入金合計 | E3: 金融機関関連 | F3: 保険関連 | G3: お客様関連 | H3: 出金合計 | I3: 金融機関関連 | J3: 買掛関連 | K3: 経費関連
B4: 44348 | C4: =SUM(C1+D4-H4) -> -14248572 | D4: =E4+F4+G4 -> 0 | E4: ='入金明細【18期】 '!D3 -> 0 | F4: ='入金明細【18期】 '!M3 -> 0 | G4: ='入金明細【18期】 '!T3 -> 0 | H4: =I4+J4+K4 -> 836496 | I4: ='出金明細【18期】'!D3 -> 0 | J4: ='出金明細【17期】'!M3 -> 0 | K4: ='出金明細【18期】'!AD3 -> 836496
B5: 44349 | C5: =SUM(C4+D5-H5) -> -14248572 | D5: =E5+F5+G5 -> 0 | E5: ='入金明細【18期】 '!D4 -> 0 | F5: ='入金明細【18期】 '!M4 -> 0 | G5: ='入金明細【18期】 '!T4 -> 0 | H5: =I5+J5+K5 -> 0 | I5: ='出金明細【18期】'!D4 -> 0 | J5: ='出金明細【18期】'!M4 -> 0 | K5: ='出金明細【18期】'!AD4 -> 0
B6: 45446 | C6: =SUM(C5+D6-H6) -> -14248572 | D6: =E6+F6+G6 -> 0 | E6: ='入金明細【18期】 '!D5 -> 0 | F6: ='入金明細【18期】 '!M5 -> 0 | G6: ='入金明細【18期】 '!T5 -> 0 | H6: =I6+J6+K6 -> 0 | I6: ='出金明細【18期】'!D5 -> 0 | J6: ='出金明細【18期】'!M5 -> 0 | K6: ='出金明細【18期】'!AD5 -> 0
B7: 44351 | C7: =SUM(C6+D7-H7) -> -14248572 | D7: =E7+F7+G7 -> 0 | E7: ='入金明細【18期】 '!D6 -> 0 | F7: ='入金明細【18期】 '!M6 -> 0 | G7: ='入金明細【18期】 '!T6 -> 0 | H7: =I7+J7+K7 -> 0 | I7: ='出金明細【18期】'!D6 -> 0 | J7: ='出金明細【18期】'!M6 -> 0 | K7: ='出金明細【18期】'!AD6 -> 0
B8: 44352 | C8: =SUM(C7+D8-H8) -> -14409372 | D8: =E8+F8+G8 -> 0 | E8: ='入金明細【18期】 '!D7 -> 0 | F8: ='入金明細【18期】 '!M7 -> 0 | G8: ='入金明細【18期】 '!T7 -> 0 | H8: =I8+J8+K8 -> 160800 | I8: ='出金明細【18期】'!D7 -> 0 | J8: ='出金明細【18期】'!M7 -> 0 | K8: ='出金明細【18期】'!AD7 -> 160800
B9: 44353 | C9: =SUM(C8+D9-H9) -> -14409372 | D9: =E9+F9+G9 -> 0 | E9: ='入金明細【18期】 '!D8 -> 0 | F9: ='入金明細【18期】 '!M8 -> 0 | G9: ='入金明細【18期】 '!T8 -> 0 | H9: =I9+J9+K9 -> 0 | I9: ='出金明細【18期】'!D8 -> 0 | J9: ='出金明細【18期】'!M8 -> 0 | K9: ='出金明細【18期】'!AD8 -> 0
B10: 44354 | C10: =SUM(C9+D10-H10) -> -14409372 | D10: =E10+F10+G10 -> 0 | E10: ='入金明細【18期】 '!D9 -> 0 | F10: ='入金明細【18期】 '!M9 -> 0 | G10: ='入金明細【18期】 '!T9 -> 0 | H10: =I10+J10+K10 -> 0 | I10: ='出金明細【18期】'!D9 -> 0 | J10: ='出金明細【18期】'!M9 -> 0 | K10: ='出金明細【18期】'!AD9 -> 0
B11: 44355 | C11: =SUM(C10+D11-H11) -> -14409372 | D11: =E11+F11+G11 -> 0 | E11: ='入金明細【18期】 '!D10 -> 0 | F11: ='入金明細【18期】 '!M10 -> 0 | G11: ='入金明細【18期】 '!T10 -> 0 | H11: =I11+J11+K11 -> 0 | I11: ='出金明細【18期】'!D10 -> 0 | J11: ='出金明細【18期】'!M10 -> 0 | K11: ='出金明細【18期】'!AD10 -> 0
B12: 44356 | C12: =SUM(C11+D12-H12) -> -18115461 | D12: =E12+F12+G12 -> 0 | E12: ='入金明細【18期】 '!D11 -> 0 | F12: ='入金明細【18期】 '!M11 -> 0 | G12: ='入金明細【18期】 '!T11 -> 0 | H12: =I12+J12+K12 -> 3706089 | I12: ='出金明細【18期】'!D11 -> 0 | J12: ='出金明細【18期】'!M11 -> 0 | K12: ='出金明細【18期】'!AD11 -> 3706089
B13: 44357 | C13: =SUM(C12+D13-H13) -> -18115461 | D13: =E13+F13+G13 -> 0 | E13: ='入金明細【18期】 '!D12 -> 0 | F13: ='入金明細【18期】 '!M12 -> 0 | G13: ='入金明細【18期】 '!T12 -> 0 | H13: =I13+J13+K13 -> 0 | I13: ='出金明細【18期】'!D12 -> 0 | J13: ='出金明細【18期】'!M12 -> 0 | K13: ='出金明細【18期】'!AD12 -> 0
B14: 44358 | C14: =SUM(C13+D14-H14) -> -18115461 | D14: =E14+F14+G14 -> 0 | E14: ='入金明細【18期】 '!D13 -> 0 | F14: ='入金明細【18期】 '!M13 -> 0 | G14: ='入金明細【18期】 '!T13 -> 0 | H14: =I14+J14+K14 -> 0 | I14: ='出金明細【18期】'!D13 -> 0 | J14: ='出金明細【18期】'!M13 -> 0 | K14: ='出金明細【18期】'!AD13 -> 0
B15: 44359 | C15: =SUM(C14+D15-H15) -> -18115461 | D15: =E15+F15+G15 -> 0 | E15: ='入金明細【18期】 '!D14 -> 0 | F15: ='入金明細【18期】 '!M14 -> 0 | G15: ='入金明細【18期】 '!T14 -> 0 | H15: =I15+J15+K15 -> 0 | I15: ='出金明細【18期】'!D14 -> 0 | J15: ='出金明細【18期】'!M14 -> 0 | K15: ='出金明細【18期】'!AD14 -> 0
B16: 44360 | C16: =SUM(C15+D16-H16) -> -18115461 | D16: =E16+F16+G16 -> 0 | E16: ='入金明細【18期】 '!D15 -> 0 | F16: ='入金明細【18期】 '!M15 -> 0 | G16: ='入金明細【18期】 '!T15 -> 0 | H16: =I16+J16+K16 -> 0 | I16: ='出金明細【18期】'!D15 -> 0 | J16: ='出金明細【18期】'!M15 -> 0 | K16: ='出金明細【18期】'!AD15 -> 0
... B33: 44377 | C33: =SUM(C32+D33-H33) -> -27736909 | D33: =E33+F33+G33 -> 0 | E33: ='入金明細【18期】 '!D32 -> 0 | F33: ='入金明細【18期】 '!M32 -> 0 | G33: ='入金明細【18期】 '!T32 -> 0 | H33: =I33+J33+K33 -> 2470488 | I33: ='出金明細【18期】'!D32 -> 2470488 | J33: ='出金明細【18期】'!M32 -> 0 | K33: ='出金明細【18期】'!AD32 -> 0
B34: 6月合計 | C34: =SUM(D34-H34) -> -14324833 | D34: =E34+F34+G34 -> 0 | E34: =SUM(E4:E33) -> 0 | F34: =SUM(F4:F33) -> 0 | G34: =SUM(G4:G33) -> 0 | H34: =SUM(H4:H33) -> 14324833 | I34: =SUM(I4:I33) -> 5269520 | J34: =SUM(J4:J33) -> 1845000 | K34: =SUM(K4:K33) -> 7210313
B35: 累計 | C35: =SUM(D35-H35) -> -14324833 | D35: =E35+F35+G35 -> 0 | E35: =E2+E34 -> 0 | F35: =F2+F34 -> 0 | G35: =G2+G34 -> 0 | H35: =H2+H34 -> 14324833 | I35: =I2+I34 -> 5269520 | J35: =J2+J34 -> 1845000 | K35: =K2+K34 -> 7210313
B36: 44378 | C36: =SUM(C33+D36-H36) -> -27819105 | D36: =E36+F36+G36 -> 0 | E36: ='入金明細【18期】 '!D35 -> 0 | F36: ='入金明細【18期】 '!M35 -> 0 | G36: ='入金明細【18期】 '!T35 -> 0 | H36: =I36+J36+K36 -> 82196 | I36: ='出金明細【18期】'!D35 -> 0 | J36: ='出金明細【18期】'!M35 -> 0 | K36: ='出金明細【18期】'!AD35 -> 82196
B37: 45109 | C37: =SUM(C36+D37-H37) -> -27848585 | D37: =E37+F37+G37 -> 0 | E37: ='入金明細【18期】 '!D36 -> 0 | F37: ='入金明細【18期】 '!M36 -> 0 | G37: ='入金明細【18期】 '!T36 -> 0 | H37: =I37+J37+K37 -> 29480 | I37: ='出金明細【18期】'!D36 -> 0 | J37: ='出金明細【18期】'!M36 -> 0 | K37: ='出金明細【18期】'!AD36 -> 29480
B38: 45110 | C38: =SUM(C37+D38-H38) -> -27848585 | D38: =E38+F38+G38 -> 0 | E38: ='入金明細【18期】 '!D37 -> 0 | F38: ='入金明細【18期】 '!M37 -> 0 | G38: ='入金明細【18期】 '!T37 -> 0 | H38: =I38+J38+K38 -> 0 | I38: ='出金明細【18期】'!D37 -> 0 | J38: ='出金明細【18期】'!M37 -> 0 | K38: ='出金明細【18期】'!AD37 -> 0
B39: 45111 | C39: =SUM(C38+D39-H39) -> -27848585 | D39: =E39+F39+G39 -> 0 | E39: ='入金明細【18期】 '!D38 -> 0 | F39: ='入金明細【18期】 '!M38 -> 0 | G39: ='入金明細【18期】 '!T38 -> 0 | H39: =I39+J39+K39 -> 0 | I39: ='出金明細【18期】'!D38 -> 0 | J39: ='出金明細【18期】'!M38 -> 0 | K39: ='出金明細【18期】'!AD38 -> 0
B40: 45112 | C40: =SUM(C39+D40-H40) -> -27936585 | D40: =E40+F40+G40 -> 0 | E40: ='入金明細【18期】 '!D39 -> 0 | F40: ='入金明細【18期】 '!M39 -> 0 | G40: ='入金明細【18期】 '!T39 -> 0 | H40: =I40+J40+K40 -> 88000 | I40: ='出金明細【18期】'!D39 -> 0 | J40: ='出金明細【18期】'!M39 -> 0 | K40: ='出金明細【18期】'!AD39 -> 88000
B41: 45113 | C41: =SUM(C40+D41-H41) -> -27936585 | D41: =E41+F41+G41 -> 0 | E41: ='入金明細【18期】 '!D40 -> 0 | F41: ='入金明細【18期】 '!M40 -> 0 | G41: ='入金明細【18期】 '!T40 -> 0 | H41: =I41+J41+K41 -> 0 | I41: ='出金明細【18期】'!D40 -> 0 | J41: ='出金明細【18期】'!M40 -> 0 | K41: ='出金明細【18期】'!AD40 -> 0
B42: 45114 | C42: =SUM(C41+D42-H42) -> -27936585 | D42: =E42+F42+G42 -> 0 | E42: ='入金明細【18期】 '!D41 -> 0 | F42: ='入金明細【18期】 '!M41 -> 0 | G42: ='入金明細【18期】 '!T41 -> 0 | H42: =I42+J42+K42 -> 0 | I42: ='出金明細【18期】'!D41 -> 0 | J42: ='出金明細【18期】'!M41 -> 0 | K42: ='出金明細【18期】'!AD41 -> 0
B43: 45115 | C43: =SUM(C42+D43-H43) -> -27936585 | D43: =E43+F43+G43 -> 0 | E43: ='入金明細【18期】 '!D42 -> 0 | F43: ='入金明細【18期】 '!M42 -> 0 | G43: ='入金明細【18期】 '!T42 -> 0 | H43: =I43+J43+K43 -> 0 | I43: ='出金明細【18期】'!D42 -> 0 | J43: ='出金明細【18期】'!M42 -> 0 | K43: ='出金明細【18期】'!AD42 -> 0
B44: 45116 | C44: =SUM(C43+D44-H44) -> -31642674 | D44: =E44+F44+G44 -> 0 | E44: ='入金明細【18期】 '!D43 -> 0 | F44: ='入金明細【18期】 '!M43 -> 0 | G44: ='入金明細【18期】 '!T43 -> 0 | H44: =I44+J44+K44 -> 3706089 | I44: ='出金明細【18期】'!D43 -> 0 | J44: ='出金明細【18期】'!M43 -> 0 | K44: ='出金明細【18期】'!AD43 -> 3706089
B45: 45117 | C45: =SUM(C44+D45-H45) -> -31642674 | D45: =E45+F45+G45 -> 0 | E45: ='入金明細【18期】 '!D44 -> 0 | F45: ='入金明細【18期】 '!M44 -> 0 | G45: ='入金明細【18期】 '!T44 -> 0 | H45: =I45+J45+K45 -> 0 | I45: ='出金明細【18期】'!D44 -> 0 | J45: ='出金明細【18期】'!M44 -> 0 | K45: ='出金明細【18期】'!AD44 -> 0
B46: 45118 | C46: =SUM(C45+D46-H46) -> -31642674 | D46: =E46+F46+G46 -> 0 | E46: ='入金明細【18期】 '!D45 -> 0 | F46: ='入金明細【18期】 '!M45 -> 0 | G46: ='入金明細【18期】 '!T45 -> 0 | H46: =I46+J46+K46 -> 0 | I46: ='出金明細【18期】'!D45 -> 0 | J46: ='出金明細【18期】'!M45 -> 0 | K46: ='出金明細【18期】'!AD45 -> 0
B47: 45119 | C47: =SUM(C46+D47-H47) -> -31642674 | D47: =E47+F47+G47 -> 0 | E47: ='入金明細【18期】 '!D46 -> 0 | F47: ='入金明細【18期】 '!M46 -> 0 | G47: ='入金明細【18期】 '!T46 -> 0 | H47: =I47+J47+K47 -> 0 | I47: ='出金明細【18期】'!D46 -> 0 | J47: ='出金明細【18期】'!M46 -> 0 | K47: ='出金明細【18期】'!AD46 -> 0
B48: 45120 | C48: =SUM(C47+D48-H48) -> -31642674 | D48: =E48+F48+G48 -> 0 | E48: ='入金明細【18期】 '!D47 -> 0 | F48: ='入金明細【18期】 '!M47 -> 0 | G48: ='入金明細【18期】 '!T47 -> 0 | H48: =I48+J48+K48 -> 0 | I48: ='出金明細【18期】'!D47 -> 0 | J48: ='出金明細【18期】'!M47 -> 0 | K48: ='出金明細【18期】'!AD47 -> 0
... B66: 45138 | C66: =SUM(C65+D66-H66) -> -66306775 | D66: =E66+F66+G66 -> 0 | E66: ='入金明細【18期】 '!D65 -> 0 | F66: ='入金明細【18期】 '!M65 -> 0 | G66: ='入金明細【18期】 '!T65 -> 0 | H66: =I66+J66+K66 -> 2470488 | I66: ='出金明細【18期】'!D65 -> 2470488 | J66: ='出金明細【18期】'!M65 -> 0 | K66: ='出金明細【18期】'!AD65 -> 0
B67: 7月合計 | C67: =SUM(D67-H67) -> -38569866 | D67: =SUM(D36:D66) -> 0 | E67: =SUM(E36:E66) -> 0 | F67: =SUM(F36:F66) -> 0 | G67: =SUM(G36:G66) -> 0 | H67: =SUM(H36:H66) -> 38569866 | I67: =SUM(I36:I66) -> 30269520 | J67: =SUM(J36:J66) -> 1895000 | K67: =SUM(K36:K66) -> 6405346
B68: 累計 | C68: =SUM(D68-H68) -> -52894699 | D68: =D35+D67 -> 0 | E68: =E35+E67 -> 0 | F68: =F35+F67 -> 0 | G68: =G35+G67 -> 0 | H68: =H35+H67 -> 52894699 | I68: =I35+I67 -> 35539040 | J68: =J35+J67 -> 3740000 | K68: =K35+K67 -> 13615659
B69: 45139 | C69: =SUM(C66+D69-H69) -> -66388971 | D69: =E69+F69+G69 -> 0 | E69: ='入金明細【18期】 '!D68 -> 0 | F69: ='入金明細【18期】 '!M68 | G69: ='入金明細【18期】 '!T68 -> 0 | H69: =I69+J69+K69 -> 82196 | I69: ='出金明細【18期】'!D68 -> 0 | J69: ='出金明細【18期】'!M68 -> 0 | K69: ='出金明細【18期】'!AD68 -> 82196
B70: 45140 | C70: =SUM(C69+D70-H70) -> -66418451 | D70: =E70+F70+G70 -> 0 | E70: ='入金明細【18期】 '!D69 -> 0 | F70: ='入金明細【18期】 '!M69 | G70: ='入金明細【18期】 '!T69 -> 0 | H70: =I70+J70+K70 -> 29480 | I70: ='出金明細【18期】'!D69 -> 0 | J70: ='出金明細【18期】'!M69 -> 0 | K70: ='出金明細【18期】'!AD69 -> 29480
B71: 45141 | C71: =SUM(C70+D71-H71) -> -66418451 | D71: =E71+F71+G71 -> 0 | E71: ='入金明細【18期】 '!D70 -> 0 | F71: ='入金明細【18期】 '!M70 | G71: ='入金明細【18期】 '!T70 -> 0 | H71: =I71+J71+K71 -> 0 | I71: ='出金明細【18期】'!D70 -> 0 | J71: ='出金明細【18期】'!M70 -> 0 | K71: ='出金明細【18期】'!AD70 -> 0
B72: 45142 | C72: =SUM(C71+D72-H72) -> -66418451 | D72: =E72+F72+G72 -> 0 | E72: ='入金明細【18期】 '!D71 -> 0 | F72: ='入金明細【18期】 '!M71 | G72: ='入金明細【18期】 '!T71 -> 0 | H72: =I72+J72+K72 -> 0 | I72: ='出金明細【18期】'!D71 -> 0 | J72: ='出金明細【18期】'!M71 -> 0 | K72: ='出金明細【18期】'!AD71 -> 0
B73: 45143 | C73: =SUM(C72+D73-H73) -> -66506451 | D73: =E73+F73+G73 -> 0 | E73: ='入金明細【18期】 '!D72 -> 0 | F73: ='入金明細【18期】 '!M72 -> 0 | G73: ='入金明細【18期】 '!T72 -> 0 | H73: =I73+J73+K73 -> 88000 | I73: ='出金明細【18期】'!D72 -> 0 | J73: ='出金明細【18期】'!M72 -> 0 | K73: ='出金明細【18期】'!AD72 -> 88000
...

Sheet 入金明細【18期】 
C1: ２０２5年６月‐２０２6年５月入金
C2: 入金日次 | D2: 金融小計 | E2: 金融機関関連 | M2: 保険小計 | N2: 保険関連 | T2: お客様小計 | U2: お客様関連
B3: 44348 | C3: =D3+M3+T3 -> 0 | D3: =F3+H3+J3+L3 -> 0 | M3: =O3+Q3+S3 -> 0 | T3: =V3+X3+Z3+AB3+AD3+AF3+AH3+AJ3+AV3+AL3+AN3+AP3+AR3+'入金明細【18期】 '!AT3 -> 0
B4: 44349 | C4: =D4+M4+T4 -> 0 | D4: =F4+H4+J4+L4 -> 0 | M4: =O4+Q4+S4 -> 0 | T4: =V4+X4+Z4+AB4+AD4+AF4+AH4+AJ4+AV4+AL4+AN4+AP4+AR4+AT4 -> 0
B5: 45446 | C5: =D5+M5+T5 -> 0 | D5: =F5+H5+J5+L5 -> 0 | M5: =O5+Q5+S5 -> 0 | T5: =V5+X5+Z5+AB5+AD5+AF5+AH5+AJ5+AV5+AL5+AN5+AP5+AR5+AT5 -> 0
B6: 44351 | C6: =D6+M6+T6 -> 0 | D6: =F6+H6+J6+L6 -> 0 | M6: =O6+Q6+S6 -> 0 | T6: =V6+X6+Z6+AB6+AD6+AF6+AH6+AJ6+AV6+AL6+AN6+AP6+AR6+AT6 -> 0
B7: 44352 | C7: =D7+M7+T7 -> 0 | D7: =F7+H7+J7+L7 -> 0 | M7: =O7+Q7+S7 -> 0 | T7: =V7+X7+Z7+AB7+AD7+AF7+AH7+AJ7+AV7+AL7+AN7+AP7+AR7+AT7 -> 0
B8: 44353 | C8: =D8+M8+T8 -> 0 | D8: =F8+H8+J8+L8 -> 0 | M8: =O8+Q8+S8 -> 0 | T8: =V8+X8+Z8+AB8+AD8+AF8+AH8+AJ8+AV8+AL8+AN8+AP8+AR8+AT8 -> 0
B9: 44354 | C9: =D9+M9+T9 -> 0 | D9: =F9+H9+J9+L9 -> 0 | M9: =O9+Q9+S9 -> 0 | T9: =V9+X9+Z9+AB9+AD9+AF9+AH9+AJ9+AV9+AL9+AN9+AP9+AR9+AT9 -> 0
B10: 45816 | C10: =D10+M10+T10 -> 0 | D10: =F10+H10+J10+L10 -> 0 | M10: =O10+Q10+S10 -> 0 | T10: =V10+X10+Z10+AB10+AD10+AF10+AH10+AJ10+AV10+AL10+AN10+AP10+AR10+AT10 -> 0
B11: 44356 | C11: =D11+M11+T11 -> 0 | D11: =F11+H11+J11+L11 -> 0 | M11: =O11+Q11+S11 -> 0 | T11: =V11+X11+Z11+AB11+AD11+AF11+AH11+AJ11+AV11+AL11+AN11+AP11+AR11+AT11 -> 0
B12: 44357 | C12: =D12+M12+T12 -> 0 | D12: =F12+H12+J12+L12 -> 0 | M12: =O12+Q12+S12 -> 0 | T12: =V12+X12+Z12+AB12+AD12+AF12+AH12+AJ12+AV12+AL12+AN12+AP12+AR12+AT12 -> 0
B13: 44358 | C13: =D13+M13+T13 -> 0 | D13: =F13+H13+J13+L13 -> 0 | M13: =O13+Q13+S13 -> 0 | T13: =V13+X13+Z13+AB13+AD13+AF13+AH13+AJ13+AV13+AL13+AN13+AP13+AR13+AT13 -> 0
B14: 44359 | C14: =D14+M14+T14 -> 0 | D14: =F14+H14+J14+L14 -> 0 | M14: =O14+Q14+S14 -> 0 | T14: =V14+X14+Z14+AB14+AD14+AF14+AH14+AJ14+AV14+AL14+AN14+AP14+AR14+AT14 -> 0
B15: 44360 | C15: =D15+M15+T15 -> 0 | D15: =F15+H15+J15+L15 -> 0 | M15: =O15+Q15+S15 -> 0 | T15: =V15+X15+Z15+AB15+AD15+AF15+AH15+AJ15+AV15+AL15+AN15+AP15+AR15+AT15 -> 0
... B32: 44377 | C32: =D32+M32+T32 -> 0 | D32: =F32+H32+J32+L32 -> 0 | M32: =O32+Q32+S32 -> 0 | T32: =V32+X32+Z32+AB32+AD32+AF32+AH32+AJ32+AV32+AL32+AN32+AP32+AR32+AT32 -> 0
B33: ６月合計 | C33: =D33+M33+T33 -> 0 | D33: =SUM(D2:D32) -> 0 | M33: =SUM(M2:M32) -> 0 | T33: =SUM(T3:T32) -> 0
B34: 未確定 | C34: =D34+M34+T34 -> 0 | T34: =V34+X34+Z34+AB34+AD34+AF34+AH34+AJ34+AV34 -> 0
B35: 44378 | C35: =D35+M35+T35 -> 0 | D35: =F35+H35+J35+L35 -> 0 | M35: =O35+Q35+S35 -> 0 | T35: =V35+X35+Z35+AB35+AD35+AF35+AH35+AJ35+AV35+AL35+AN35+AP35+AR35+AT35 -> 0
B36: 45109 | C36: =D36+M36+T36 -> 0 | D36: =F36+H36+J36+L36 -> 0 | M36: =O36+Q36+S36 -> 0 | T36: =V36+X36+Z36+AB36+AD36+AF36+AH36+AJ36+AV36+AL36+AN36+AP36+AR36+AT36 -> 0
B37: 45110 | C37: =D37+M37+T37 -> 0 | D37: =F37+H37+J37+L37 -> 0 | M37: =O37+Q37+S37 -> 0 | T37: =V37+X37+Z37+AB37+AD37+AF37+AH37+AJ37+AV37+AL37+AN37+AP37+AR37+AT37 -> 0
B38: 45111 | C38: =D38+M38+T38 -> 0 | D38: =F38+H38+J38+L38 -> 0 | M38: =O38+Q38+S38 -> 0 | T38: =V38+X38+Z38+AB38+AD38+AF38+AH38+AJ38+AV38+AL38+AN38+AP38+AR38+AT38 -> 0
B39: 45112 | C39: =D39+M39+T39 -> 0 | D39: =F39+H39+J39+L39 -> 0 | M39: =O39+Q39+S39 -> 0 | T39: =V39+X39+Z39+AB39+AD39+AF39+AH39+AJ39+AV39+AL39+AN39+AP39+AR39+AT39 -> 0
B40: 45113 | C40: =D40+M40+T40 -> 0 | D40: =F40+H40+J40+L40 -> 0 | M40: =O40+Q40+S40 -> 0 | T40: =V40+X40+Z40+AB40+AD40+AF40+AH40+AJ40+AV40+AL40+AN40+AP40+AR40+AT40 -> 0
B41: 45114 | C41: =D41+M41+T41 -> 0 | D41: =F41+H41+J41+L41 -> 0 | M41: =O41+Q41+S41 -> 0 | T41: =V41+X41+Z41+AB41+AD41+AF41+AH41+AJ41+AV41+AL41+AN41+AP41+AR41+AT41 -> 0
B42: 45115 | C42: =D42+M42+T42 -> 0 | D42: =F42+H42+J42+L42 -> 0 | M42: =O42+Q42+S42 -> 0 | T42: =V42+X42+Z42+AB42+AD42+AF42+AH42+AJ42+AV42+AL42+AN42+AP42+AR42+AT42 -> 0
B43: 45116 | C43: =D43+M43+T43 -> 0 | D43: =F43+H43+J43+L43 -> 0 | M43: =O43+Q43+S43 -> 0 | T43: =V43+X43+Z43+AB43+AD43+AF43+AH43+AJ43+AV43+AL43+AN43+AP43+AR43+AT43 -> 0
B44: 45117 | C44: =D44+M44+T44 -> 0 | D44: =F44+H44+J44+L44 -> 0 | M44: =O44+Q44+S44 -> 0 | T44: =V44+X44+Z44+AB44+AD44+AF44+AH44+AJ44+AV44+AL44+AN44+AP44+AR44+AT44 -> 0
B45: 45118 | C45: =D45+M45+T45 -> 0 | D45: =F45+H45+J45+L45 -> 0 | M45: =O45+Q45+S45 -> 0 | T45: =V45+X45+Z45+AB45+AD45+AF45+AH45+AJ45+AV45+AL45+AN45+AP45+AR45+AT45 -> 0
B46: 45119 | C46: =D46+M46+T46 -> 0 | D46: =F46+H46+J46+L46 -> 0 | M46: =O46+Q46+S46 -> 0 | T46: =V46+X46+Z46+AB46+AD46+AF46+AH46+AJ46+AV46+AL46+AN46+AP46+AR46+AT46 -> 0
... B65: 45138 | C65: =D65+M65+T65 -> 0 | D65: =F65+H65+J65+L65 -> 0 | M65: =O65+Q65+S65 -> 0 | T65: =V65+X65+Z65+AB65+AD65+AF65+AH65+AJ65+AV65+AL65+AN65+AP65+AR65+AT65 -> 0
B66: ７月合計 | C66: =D66+M66+T66 -> 0 | D66: =SUM(D35:D65) -> 0 | M66: =SUM(M35:M65) -> 0 | T66: =SUM(T35:T65) -> 0
B67: 未確定 | C67: =D67+M67+T67 -> 0 | T67: =V67+X67+Z67+AB67+AD67+AF67+AH67+AJ67+AV67 -> 0
B68: 45139 | C68: =D68+M68+T68 -> 0 | D68: =F68+H68+J68+L68 -> 0 | M68: =O68 | T68: =V68+X68+Z68+AB68+AD68+AF68+AH68+AJ68+AV68 -> 0
B69: 45140 | C69: =D69+M69+T69 -> 0 | D69: =F69+H69+J69+L69 -> 0 | M69: =O69 | T69: =V69+X69+Z69+AB69+AD69+AF69+AH69+AJ69+AV69 -> 0
B70: 45141 | C70: =D70+M70+T70 -> 0 | D70: =F70+H70+J70+L70 -> 0 | M70: =O70 | T70: =V70+X70+Z70+AB70+AD70+AF70+AH70+AJ70+AV70 -> 0
B71: 45142 | C71: =D71+M71+T71 -> 0 | D71: =F71+H71+J71+L71 -> 0 | M71: =O71 | T71: =V71+X71+Z71+AB71+AD71+AF71+AH71+AJ71+AV71 -> 0
B72: 45143 | C72: =D72+M72+T72 -> 0 | D72: =F72+H72+J72+L72 -> 0 | M72: =O72+Q72 -> 0 | T72: =V72+X72+Z72+AB72+AD72+AF72+AH72+AJ72+AV72 -> 0
B73: 45144 | C73: =D73+M73+T73 -> 0 | D73: =F73+H73+J73+L73 -> 0 | M73: =O73+Q73 -> 0 | T73: =V73+X73+Z73+AB73+AD73+AF73+AH73+AJ73+AV73 -> 0
B74: 45145 | C74: =D74+M74+T74 -> 0 | D74: =F74+H74+J74+L74 -> 0 | M74: =O74+Q74 -> 0 | T74: =V74+X74+Z74+AB74+AD74+AF74+AH74+AJ74+AV74 -> 0
...

Sheet 出金明細【18期】
C1: ２０２6年６月‐２０２7年５月出金
C2: 出金日次 | D2: 金融小計 | M2: 買掛小計 | AD2: 経費小計
B3: 44348 | C3: =D3+M3+AD3 -> 836496 | D3: =F3+H3+J3+L3 -> 0 | M3: =O3+Q3+S3+U3+W3+Y3+AA3+AC3 -> 0 | AD3: =AF3+AH3+AJ3+AL3+AN3+AP3+AR3+AT3+AV3+AX3+AZ3+BB3+BD3+BF3+BH3+BJ3+BL3+BN3+BP3+BR3+BT3+BV3+BX3+BZ3+CB3+CD3 -> 836496 | AE3: も）ﾄﾖﾀﾌｧｲﾅﾝｽ | AF3: 82196 | AG3: 自動車税 | AH3: 754300
B4: 44349 | C4: =D4+M4+AD4 -> 0 | D4: =F4+H4+J4+L4 -> 0 | M4: =O4+Q4+S4+U4+W4+Y4+AA4+AC4 -> 0 | AD4: =AF4+AH4+AJ4+AL4+AN4+AP4+AR4+AT4+AV4+AX4+AZ4+BB4+BD4+BF4+BH4+BJ4+BL4+BN4+BP4+BR4+BT4+BV4+BX4+BZ4+CB4+CD4 -> 0
B5: 45446 | C5: =D5+M5+AD5 -> 0 | D5: =F5+H5+J5+L5 -> 0 | M5: =O5+Q5+S5+U5+W5+Y5+AA5+AC5 -> 0 | AD5: =AF5+AH5+AJ5+AL5+AN5+AP5+AR5+AT5+AV5+AX5+AZ5+BB5+BD5+BF5+BH5+BJ5+BL5+BN5+BP5+BR5+BT5+BV5+BX5+BZ5+CB5+CD5 -> 0
B6: 44351 | C6: =D6+M6+AD6 -> 0 | D6: =F6+H6+J6+L6 -> 0 | M6: =O6+Q6+S6+U6+W6+Y6+AA6+AC6 -> 0 | AD6: =AF6+AH6+AJ6+AL6+AN6+AP6+AR6+AT6+AV6+AX6+AZ6+BB6+BD6+BF6+BH6+BJ6+BL6+BN6+BP6+BR6+BT6+BV6+BX6+BZ6+CB6+CD6 -> 0
B7: 44352 | C7: =D7+M7+AD7 -> 160800 | D7: =F7+H7+J7+L7 -> 0 | M7: =O7+Q7+S7+U7+W7+Y7+AA7+AC7 -> 0 | AD7: =AF7+AH7+AJ7+AL7+AN7+AP7+AR7+AT7+AV7+AX7+AZ7+BB7+BD7+BF7+BH7+BJ7+BL7+BN7+BP7+BR7+BT7+BV7+BX7+BZ7+CB7+CD7 -> 160800 | AE7: 笠)未来経営 | AF7: 88000 | AG7: 住民税 | AH7: 72800
B8: 44353 | C8: =D8+M8+AD8 -> 0 | D8: =F8+H8+J8+L8 -> 0 | M8: =O8+Q8+S8+U8+W8+Y8+AA8+AC8 -> 0 | AD8: =AF8+AH8+AJ8+AL8+AN8+AP8+AR8+AT8+AV8+AX8+AZ8+BB8+BD8+BF8+BH8+BJ8+BL8+BN8+BP8+BR8+BT8+BV8+BX8+BZ8+CB8+CD8 -> 0
B9: 44354 | C9: =D9+M9+AD9 -> 0 | D9: =F9+H9+J9+L9 -> 0 | M9: =O9+Q9+S9+U9+W9+Y9+AA9+AC9 -> 0 | AD9: =AF9+AH9+AJ9+AL9+AN9+AP9+AR9+AT9+AV9+AX9+AZ9+BB9+BD9+BF9+BH9+BJ9+BL9+BN9+BP9+BR9+BT9+BV9+BX9+BZ9+CB9+CD9 -> 0
B10: 45816 | C10: =D10+M10+AD10 -> 0 | D10: =F10+H10+J10+L10 -> 0 | M10: =O10+Q10+S10+U10+W10+Y10+AA10+AC10 -> 0 | AD10: =AF10+AH10+AJ10+AL10+AN10+AP10+AR10+AT10+AV10+AX10+AZ10+BB10+BD10+BF10+BH10+BJ10+BL10+BN10+BP10+BR10+BT10+BV10+BX10+BZ10+CB10+CD10 -> 0
B11: 44356 | C11: =D11+M11+AD11 -> 3706089 | D11: =F11+H11+J11+L11 -> 0 | M11: =O11+Q11+S11+U11+W11+Y11+AA11+AC11 -> 0 | AD11: =AF11+AH11+AJ11+AL11+AN11+AP11+AR11+AT11+AV11+AX11+AZ11+BB11+BD11+BF11+BH11+BJ11+BL11+BN11+BP11+BR11+BT11+BV11+BX11+BZ11+CB11+CD11 -> 3706089 | AE11: 銚子部長 | AF11: 100000 | AG11: 笠）ﾀﾞｲﾅｰｽﾞ | AH11: 177132 | AI11: も)整備ﾀﾞｲﾅｰｽｶｰﾄﾞ・ﾄﾗｽﾄｸﾗﾌﾞ | AJ11: 593649 | AK11: も)ﾀﾞｲﾅｰｽｶｰﾄﾞ・ﾄﾗｽﾄｸﾗﾌﾞ | AL11: 455500 | AM11: 田中賢治様 | AN11: 14600 | AO11: 給与 | AP11: 1123735 | AQ11: 高田自動車 | AR11: 512973 | AS11: 大中誠二 | AT11: =600000+128500 -> 728500
B12: 44357 | C12: =D12+M12+AD12 -> 0 | D12: =F12+H12+J12+L12 -> 0 | M12: =O12+Q12+S12+U12+W12+Y12+AA12+AC12 -> 0 | AD12: =AF12+AH12+AJ12+AL12+AN12+AP12+AR12+AT12+AV12+AX12+AZ12+BB12+BD12+BF12+BH12+BJ12+BL12+BN12+BP12+BR12+BT12+BV12+BX12+BZ12+CB12+CD12 -> 0
B13: 44358 | C13: =D13+M13+AD13 -> 0 | D13: =F13+H13+J13+L13 -> 0 | M13: =O13+Q13+S13+U13+W13+Y13+AA13+AC13 -> 0 | AD13: =AF13+AH13+AJ13+AL13+AN13+AP13+AR13+AT13+AV13+AX13+AZ13+BB13+BD13+BF13+BH13+BJ13+BL13+BN13+BP13+BR13+BT13+BV13+BX13+BZ13+CB13+CD13 -> 0
B14: 44359 | C14: =D14+M14+AD14 -> 0 | D14: =F14+H14+J14+L14 -> 0 | M14: =O14+Q14+S14+U14+W14+Y14+AA14+AC14 -> 0 | AD14: =AF14+AH14+AJ14+AL14+AN14+AP14+AR14+AT14+AV14+AX14+AZ14+BB14+BD14+BF14+BH14+BJ14+BL14+BN14+BP14+BR14+BT14+BV14+BX14+BZ14+CB14+CD14 -> 0
B15: 44360 | C15: =D15+M15+AD15 -> 0 | D15: =F15+H15+J15+L15 -> 0 | M15: =O15+Q15+S15+U15+W15+Y15+AA15+AC15 -> 0 | AD15: =AF15+AH15+AJ15+AL15+AN15+AP15+AR15+AT15+AV15+AX15+AZ15+BB15+BD15+BF15+BH15+BJ15+BL15+BN15+BP15+BR15+BT15+BV15+BX15+BZ15+CB15+CD15 -> 0
B16: 44361 | C16: =D16+M16+AD16 -> 0 | D16: =F16+H16+J16+L16 -> 0 | M16: =O16+Q16+S16+U16+W16+Y16+AA16+AC16 -> 0 | AD16: =AF16+AH16+AJ16+AL16+AN16+AP16+AR16+AT16+AV16+AX16+AZ16+BB16+BD16+BF16+BH16+BJ16+BL16+BN16+BP16+BR16+BT16+BV16+BX16+BZ16+CB16+CD16 -> 0
B17: 44362 | C17: =D17+M17+AD17 -> 0 | D17: =F17+H17+J17+L17 -> 0 | M17: =O17+Q17+S17+U17+W17+Y17+AA17+AC17 -> 0 | AD17: =AF17+AH17+AJ17+AL17+AN17+AP17+AR17+AT17+AV17+AX17+AZ17+BB17+BD17+BF17+BH17+BJ17+BL17+BN17+BP17+BR17+BT17+BV17+BX17+BZ17+CB17+CD17 -> 0
B18: 44363 | C18: =D18+M18+AD18 -> 0 | D18: =F18+H18+J18+L18 -> 0 | M18: =O18+Q18+S18+U18+W18+Y18+AA18+AC18 -> 0 | AD18: =AF18+AH18+AJ18+AL18+AN18+AP18+AR18+AT18+AV18+AX18+AZ18+BB18+BD18+BF18+BH18+BJ18+BL18+BN18+BP18+BR18+BT18+BV18+BX18+BZ18+CB18+CD18 -> 0
B19: 44364 | C19: =D19+M19+AD19 -> 0 | D19: =F19+H19+J19+L19 -> 0 | M19: =O19+Q19+S19+U19+W19+Y19+AA19+AC19 -> 0 | AD19: =AF19+AH19+AJ19+AL19+AN19+AP19+AR19+AT19+AV19+AX19+AZ19+BB19+BD19+BF19+BH19+BJ19+BL19+BN19+BP19+BR19+BT19+BV19+BX19+BZ19+CB19+CD19 -> 0
B20: 44365 | C20: =D20+M20+AD20 -> 0 | D20: =F20+H20+J20+L20 -> 0 | M20: =O20+Q20+S20+U20+W20+Y20+AA20+AC20 -> 0 | AD20: =AF20+AH20+AJ20+AL20+AN20+AP20+AR20+AT20+AV20+AX20+AZ20+BB20+BD20+BF20+BH20+BJ20+BL20+BN20+BP20+BR20+BT20+BV20+BX20+BZ20+CB20+CD20 -> 0
B21: 44366 | C21: =D21+M21+AD21 -> 0 | D21: =F21+H21+J21+L21 -> 0 | M21: =O21+Q21+S21+U21+W21+Y21+AA21+AC21 -> 0 | AD21: =AF21+AH21+AJ21+AL21+AN21+AP21+AR21+AT21+AV21+AX21+AZ21+BB21+BD21+BF21+BH21+BJ21+BL21+BN21+BP21+BR21+BT21+BV21+BX21+BZ21+CB21+CD21 -> 0
B22: 44367 | C22: =D22+M22+AD22 -> 0 | D22: =F22+H22+J22+L22 -> 0 | M22: =O22+Q22+S22+U22+W22+Y22+AA22+AC22 -> 0 | AD22: =AF22+AH22+AJ22+AL22+AN22+AP22+AR22+AT22+AV22+AX22+AZ22+BB22+BD22+BF22+BH22+BJ22+BL22+BN22+BP22+BR22+BT22+BV22+BX22+BZ22+CB22+CD22 -> 0
B23: 44368 | C23: =D23+M23+AD23 -> 33000 | D23: =F23+H23+J23+L23 -> 0 | M23: =O23+Q23+S23+U23+W23+Y23+AA23+AC23 -> 0 | AD23: =AF23+AH23+AJ23+AL23+AN23+AP23+AR23+AT23+AV23+AX23+AZ23+BB23+BD23+BF23+BH23+BJ23+BL23+BN23+BP23+BR23+BT23+BV23+BX23+BZ23+CB23+CD23 -> 33000 | AE23: 笠）㈱ﾌﾟﾛﾄｺｰﾎﾟﾚｰｼｮﾝ | AF23: 33000
B24: 44369 | C24: =D24+M24+AD24 -> 34302 | D24: =F24+H24+J24+L24 -> 0 | M24: =O24+Q24+S24+U24+W24+Y24+AA24+AC24 -> 0 | AD24: =AF24+AH24+AJ24+AL24+AN24+AP24+AR24+AT24+AV24+AX24+AZ24+BB24+BD24+BF24+BH24+BJ24+BL24+BN24+BP24+BR24+BT24+BV24+BX24+BZ24+CB24+CD24 -> 34302 | AE24: も）ｷｬﾉﾝ | AF24: 12160 | AG24: も)水道料J&LR | AH24: 3630 | AI24: 広）本社水道代引落 | AJ24: 4202 | AK24: も)本社水道代引落 | AL24: 14310
B25: 44370 | C25: =D25+M25+AD25 -> 39003 | D25: =F25+H25+J25+L25 -> 0 | M25: =O25+Q25+S25+U25+W25+Y25+AA25+AC25 -> 0 | AD25: =AF25+AH25+AJ25+AL25+AN25+AP25+AR25+AT25+AV25+AX25+AZ25+BB25+BD25+BF25+BH25+BJ25+BL25+BN25+BP25+BR25+BT25+BV25+BX25+BZ25+CB25+CD25 -> 39003 | AE25: 三井住友車両保険対人対物17.520円＋販売車車両保険8.894円 | AF25: 39003
B26: 44371 | C26: =D26+M26+AD26 -> 0 | D26: =F26+H26+J26+L26 -> 0 | M26: =O26+Q26+S26+U26+W26+Y26+AA26+AC26 -> 0 | AD26: =AF26+AH26+AJ26+AL26+AN26+AP26+AR26+AT26+AV26+AX26+AZ26+BB26+BD26+BF26+BH26+BJ26+BL26+BN26+BP26+BR26+BT26+BV26+BX26+BZ26+CB26+CD26 -> 0
B27: 44372 | C27: =D27+M27+AD27 -> 2049400 | D27: =F27+H27+J27+L27 -> 0 | M27: =O27+Q27+S27+U27+W27+Y27+AA27+AC27 -> 1845000 | N27: ﾌﾚｯﾁｪ・ﾎﾞｽｺ | O27: 55000 | P27: SoleilﾏｾﾗﾃｨMC20賃貸借2024.9.1～2026.8.31 | Q27: 220000 | R27: 橋本商事（裕太郎さん） | S27: 1570000 | AD27: =AF27+AH27+AJ27+AL27+AN27+AP27+AR27+AT27+AV27+AX27+AZ27+BB27+BD27+BF27+BH27+BJ27+BL27+BN27+BP27+BR27+BT27+BV27+BX27+BZ27+CB27+CD27 -> 204400 | AE27: も）㈱ﾕﾆﾏｯﾄﾗｲﾌ | AF27: 4400 | AG27: 一真ｸﾞﾚｶｰﾚGT（毎月25）2026.4.1～2027.4.30 | AH27: 200000
B28: 44373 | C28: =D28+M28+AD28 -> 536158 | D28: =F28+H28+J28+L28 -> 0 | M28: =O28+Q28+S28+U28+W28+Y28+AA28+AC28 -> 0 | AD28: =AF28+AH28+AJ28+AL28+AN28+AP28+AR28+AT28+AV28+AX28+AZ28+BB28+BD28+BF28+BH28+BJ28+BL28+BN28+BP28+BR28+BT28+BV28+BX28+BZ28+CB28+CD28 -> 536158 | AE28: 笠)カープレミアクラブディーラー ゴールド会員費 | AF28: 33000 | AG28: 広）ｿﾌﾄﾊﾞﾝｸ | AH28: 44360 | AI28: も）ｶｰｾﾌﾞﾝﾃﾞｼﾞﾌｨｰﾙﾄﾞｲﾝｽﾏｰﾄｼｽﾃﾑ | AJ28: 4620 | AK28: も）まるとく本社ｺﾋﾟｰ機 | AL28: 1829 | AM28: も）ﾁｭｰﾘｯﾋ生命 | AN28: 6015 | AO28: も）ｵﾘｺｶｰｻｺﾋﾟｰ機 | AP28: 27293 | AQ28: も）あんしん生命 | AR28: 58201 | AS28: も）三和地所 | AT28: 67440 | AU28: も)ｵﾘｺJCM | AV28: 99000 | AW28: も)引落中国新聞 | AX28: 3900 | AY28: 笠）三井損害保険 | AZ28: 172790 | BA28: 中)USS月会費 | BB28: 12980 | BC28: も）㈱ﾕﾆﾏｯﾄﾗｲﾌ | BD28: 4730
B29: 44374 | C29: =D29+M29+AD29 -> 0 | D29: =F29+H29+J29+L29 -> 0 | M29: =O29+Q29+S29+U29+W29+Y29+AA29+AC29 -> 0 | AD29: =AF29+AH29+AJ29+AL29+AN29+AP29+AR29+AT29+AV29+AX29+AZ29+BB29+BD29+BF29+BH29+BJ29+BL29+BN29+BP29+BR29+BT29+BV29+BX29+BZ29+CB29+CD29 -> 0
B30: 44375 | C30: =D30+M30+AD30 -> 378785 | D30: =F30+H30+J30+L30 -> 378785 | E30: 笠信ｼｮｳｶﾝｷﾝ | F30: 378785 | M30: =O30+Q30+S30+U30+W30+Y30+AA30+AC30 -> 0 | AD30: =AF30+AH30+AJ30+AL30+AN30+AP30+AR30+AT30+AV30+AX30+AZ30+BB30+BD30+BF30+BH30+BJ30+BL30+BN30+BP30+BR30+BT30+BV30+BX30+BZ30+CB30+CD30 -> 0
B31: 44376 | C31: =D31+M31+AD31 -> 4080312 | D31: =F31+H31+J31+L31 -> 2420247 | E31: 笠信ｼｮｳｶﾝｷﾝ | F31: 1764948 | G31: も)支払利息 | H31: 33698 | I31: 笠信ｼｮｳｶﾞｼ | J31: 517560 | K31: 笠信貸付利息 | L31: 104041 | M31: =O31+Q31+S31+U31+W31+Y31+AA31+AC31 -> 0 | AD31: =AF31+AH31+AJ31+AL31+AN31+AP31+AR31+AT31+AV31+AX31+AZ31+BB31+BD31+BF31+BH31+BJ31+BL31+BN31+BP31+BR31+BT31+BV31+BX31+BZ31+CB31+CD31 -> 1660065 | AE31: 笠）福山年金事務所 | AF31: 467620 | AG31: も)ﾋﾞｰﾌｨｰﾙﾄﾞ | AH31: 2200 | AI31: 吉野ｶﾞﾚｰｼﾞ | AJ31: 165000 | AK31: ウツミ屋証券 | AL31: 160000 | AM31: 月末支払（経費） | AN31: 865245
B32: 44377 | C32: =D32+M32+AD32 -> 2470488 | D32: =F32+H32+J32+L32 -> 2470488 | E32: 笠信ｼｮｳｶﾞｼ | F32: 391779 | G32: 笠信ｼｮｳｶﾞｼ | H32: 1699552 | I32: 笠信1500万円借入 | J32: 149842 | K32: 笠信5000利息分 | L32: 229315 | M32: =O32+Q32+S32+U32+W32+Y32+AA32+AC32 -> 0 | AD32: =AF32+AH32+AJ32+AL32+AN32+AP32+AR32+AT32+AV32+AX32+AZ32+BB32+BD32+BF32+BH32+BJ32+BL32+BN32+BP32+BR32+BT32+BV32+BX32+BZ32+CB32+CD32 -> 0
B33: ６月合計 | C33: =D33+M33+AD33 -> 14324833 | D33: =SUM(D3:D32) -> 5269520 | M33: =SUM(M3:M32) -> 1845000 | AD33: =SUM(AD3:AD32) -> 7210313
B34: 未確定
B35: 44378 | C35: =D35+M35+AD35 -> 82196 | D35: =F35+H35+J35+L35 -> 0 | M35: =O35+Q35+S35+U35+W35+Y35+AA35+AC35 -> 0 | AD35: =AF35+AH35+AJ35+AL35+AN35+AP35+AR35+AT35+AV35+AX35+AZ35+BB35+BD35+BF35+BH35+BJ35+BL35+BN35+BP35+BR35+BT35+BV35+BX35+BZ35+CB35+CD35 -> 82196 | AE35: も）ﾄﾖﾀﾌｧｲﾅﾝｽ | AF35: 82196
B36: 45109 | C36: =D36+M36+AD36 -> 29480 | D36: =F36+H36+J36+L36 -> 0 | M36: =O36+Q36+S36+U36+W36+Y36+AA36+AC36 -> 0 | AD36: =AF36+AH36+AJ36+AL36+AN36+AP36+AR36+AT36+AV36+AX36+AZ36+BB36+BD36+BF36+BH36+BJ36+BL36+BN36+BP36+BR36+BT36+BV36+BX36+BZ36+CB36+CD36 -> 29480 | AE36: 三井住友FL（SM） | AF36: 29480
B37: 45110 | C37: =D37+M37+AD37 -> 0 | D37: =F37+H37+J37+L37 -> 0 | M37: =O37+Q37+S37+U37+W37+Y37+AA37+AC37 -> 0 | AD37: =AF37+AH37+AJ37+AL37+AN37+AP37+AR37+AT37+AV37+AX37+AZ37+BB37+BD37+BF37+BH37+BJ37+BL37+BN37+BP37+BR37+BT37+BV37+BX37+BZ37+CB37+CD37 -> 0
B38: 45111 | C38: =D38+M38+AD38 -> 0 | D38: =F38+H38+J38+L38 -> 0 | M38: =O38+Q38+S38+U38+W38+Y38+AA38+AC38 -> 0 | AD38: =AF38+AH38+AJ38+AL38+AN38+AP38+AR38+AT38+AV38+AX38+AZ38+BB38+BD38+BF38+BH38+BJ38+BL38+BN38+BP38+BR38+BT38+BV38+BX38+BZ38+CB38+CD38 -> 0
B39: 45112 | C39: =D39+M39+AD39 -> 88000 | D39: =F39+H39+J39+L39 -> 0 | M39: =O39+Q39+S39+U39+W39+Y39+AA39+AC39 -> 0 | AD39: =AF39+AH39+AJ39+AL39+AN39+AP39+AR39+AT39+AV39+AX39+AZ39+BB39+BD39+BF39+BH39+BJ39+BL39+BN39+BP39+BR39+BT39+BV39+BX39+BZ39+CB39+CD39 -> 88000 | AE39: 笠)未来経営 | AF39: 88000
B40: 45113 | C40: =D40+M40+AD40 -> 0 | D40: =F40+H40+J40+L40 -> 0 | M40: =O40+Q40+S40+U40+W40+Y40+AA40+AC40 -> 0 | AD40: =AF40+AH40+AJ40+AL40+AN40+AP40+AR40+AT40+AV40+AX40+AZ40+BB40+BD40+BF40+BH40+BJ40+BL40+BN40+BP40+BR40+BT40+BV40+BX40+BZ40+CB40+CD40 -> 0
...

Sheet 入出金合計表 【第17期2025年6月～】
B1: 2024年5月末残 | C1: ='入出金合計表 【第16期2024年6月～】 '!C391 -> 14462720
C2: ２０２5年６月‐２０２6年５月残高
C3: 残高日次 | D3: 入金合計 | E3: 金融機関関連 | F3: 保険関連 | G3: お客様関連 | H3: 出金合計 | I3: 金融機関関連 | J3: 買掛関連 | K3: 経費関連
B4: 44348 | C4: =SUM(C1+D4-H4) -> 12730156 | D4: =E4+F4+G4 -> 0 | E4: ='入金明細【17期】'!D3 -> 0 | F4: ='入金明細【17期】'!M3 -> 0 | G4: ='入金明細【17期】'!T3 -> 0 | H4: =I4+J4+K4 -> 1732564 | I4: ='出金明細【17期】'!D3 -> 1732564 | J4: ='出金明細【17期】'!M3 -> 0 | K4: ='出金明細【17期】'!AD3 -> 0
B5: 44349 | C5: =SUM(C4+D5-H5) -> 6503999 | D5: =E5+F5+G5 -> 0 | E5: ='入金明細【17期】'!D4 -> 0 | F5: ='入金明細【17期】'!M4 -> 0 | G5: ='入金明細【17期】'!T4 -> 0 | H5: =I5+J5+K5 -> 6226157 | I5: ='出金明細【17期】'!D4 -> 3224600 | J5: ='出金明細【17期】'!M4 -> 1043380 | K5: ='出金明細【17期】'!AD4 -> 1958177
B6: 45446 | C6: =SUM(C5+D6-H6) -> 8238989 | D6: =E6+F6+G6 -> 1930350 | E6: ='入金明細【17期】'!D5 -> 600000 | F6: ='入金明細【17期】'!M5 -> 0 | G6: ='入金明細【17期】'!T5 -> 1330350 | H6: =I6+J6+K6 -> 195360 | I6: ='出金明細【17期】'!D5 -> 0 | J6: ='出金明細【17期】'!M5 -> 0 | K6: ='出金明細【17期】'!AD5 -> 195360
B7: 44351 | C7: =SUM(C6+D7-H7) -> 8174199 | D7: =E7+F7+G7 -> 77000 | E7: ='入金明細【17期】'!D6 -> 0 | F7: ='入金明細【17期】'!M6 -> 0 | G7: ='入金明細【17期】'!T6 -> 77000 | H7: =I7+J7+K7 -> 141790 | I7: ='出金明細【17期】'!D6 -> 550 | J7: ='出金明細【17期】'!M6 -> 0 | K7: ='出金明細【17期】'!AD6 -> 141240
B8: 44352 | C8: =SUM(C7+D8-H8) -> 8239979 | D8: =E8+F8+G8 -> 65780 | E8: ='入金明細【17期】'!D7 -> 0 | F8: ='入金明細【17期】'!M7 -> 0 | G8: ='入金明細【17期】'!T7 -> 65780 | H8: =I8+J8+K8 -> 0 | I8: ='出金明細【17期】'!D7 -> 0 | J8: ='出金明細【17期】'!M7 -> 0 | K8: ='出金明細【17期】'!AD7 -> 0
B9: 44353 | C9: =SUM(C8+D9-H9) -> 8239979 | D9: =E9+F9+G9 -> 0 | E9: ='入金明細【17期】'!D8 -> 0 | F9: ='入金明細【17期】'!M8 -> 0 | G9: ='入金明細【17期】'!T8 -> 0 | H9: =I9+J9+K9 -> 0 | I9: ='出金明細【17期】'!D8 -> 0 | J9: ='出金明細【17期】'!M8 -> 0 | K9: ='出金明細【17期】'!AD8 -> 0
B10: 44354 | C10: =SUM(C9+D10-H10) -> 8264979 | D10: =E10+F10+G10 -> 25000 | E10: ='入金明細【17期】'!D9 -> 0 | F10: ='入金明細【17期】'!M9 -> 0 | G10: ='入金明細【17期】'!T9 -> 25000 | H10: =I10+J10+K10 -> 0 | I10: ='出金明細【17期】'!D9 -> 0 | J10: ='出金明細【17期】'!M9 -> 0 | K10: ='出金明細【17期】'!AD9 -> 0
B11: 44355 | C11: =SUM(C10+D11-H11) -> 8261349 | D11: =E11+F11+G11 -> 0 | E11: ='入金明細【17期】'!D10 -> 0 | F11: ='入金明細【17期】'!M10 -> 0 | G11: ='入金明細【17期】'!T10 -> 0 | H11: =I11+J11+K11 -> 3630 | I11: ='出金明細【17期】'!D10 -> 3630 | J11: ='出金明細【17期】'!M10 -> 0 | K11: ='出金明細【17期】'!AD10 -> 0
B12: 44356 | C12: =SUM(C11+D12-H12) -> 8246637 | D12: =E12+F12+G12 -> 248 | E12: ='入金明細【17期】'!D11 -> 248 | F12: ='入金明細【17期】'!M11 -> 0 | G12: ='入金明細【17期】'!T11 -> 0 | H12: =I12+J12+K12 -> 14960 | I12: ='出金明細【17期】'!D11 -> 14960 | J12: ='出金明細【17期】'!M11 -> 0 | K12: ='出金明細【17期】'!AD11 -> 0
B13: 44357 | C13: =SUM(C12+D13-H13) -> 4205693 | D13: =E13+F13+G13 -> 0 | E13: ='入金明細【17期】'!D12 -> 0 | F13: ='入金明細【17期】'!M12 -> 0 | G13: ='入金明細【17期】'!T12 -> 0 | H13: =I13+J13+K13 -> 4040944 | I13: ='出金明細【17期】'!D12 -> 5170 | J13: ='出金明細【17期】'!M12 -> 0 | K13: ='出金明細【17期】'!AD12 -> 4035774
B14: 44358 | C14: =SUM(C13+D14-H14) -> 6215267 | D14: =E14+F14+G14 -> 2009574 | E14: ='入金明細【17期】'!D13 -> 0 | F14: ='入金明細【17期】'!M13 -> 0 | G14: ='入金明細【17期】'!T13 -> 2009574 | H14: =I14+J14+K14 -> 0 | I14: ='出金明細【17期】'!D13 -> 0 | J14: ='出金明細【17期】'!M13 -> 0 | K14: ='出金明細【17期】'!AD13 -> 0
B15: 44359 | C15: =SUM(C14+D15-H15) -> 6189834 | D15: =E15+F15+G15 -> 0 | E15: ='入金明細【17期】'!D14 -> 0 | F15: ='入金明細【17期】'!M14 -> 0 | G15: ='入金明細【17期】'!T14 -> 0 | H15: =I15+J15+K15 -> 25433 | I15: ='出金明細【17期】'!D14 -> 0 | J15: ='出金明細【17期】'!M14 -> 0 | K15: ='出金明細【17期】'!AD14 -> 25433
B16: 44360 | C16: =SUM(C15+D16-H16) -> 8084834 | D16: =E16+F16+G16 -> 1900000 | E16: ='入金明細【17期】'!D15 -> 1900000 | F16: ='入金明細【17期】'!M15 -> 0 | G16: ='入金明細【17期】'!T15 -> 0 | H16: =I16+J16+K16 -> 5000 | I16: ='出金明細【17期】'!D15 -> 0 | J16: ='出金明細【17期】'!M15 -> 0 | K16: ='出金明細【17期】'!AD15 -> 5000
... B33: 44377 | C33: =SUM(C32+D33-H33) -> 7192718 | D33: =E33+F33+G33 -> 16042404 | E33: ='入金明細【17期】'!D32 -> 0 | F33: ='入金明細【17期】'!M32 -> 0 | G33: ='入金明細【17期】'!T32 -> 16042404 | H33: =I33+J33+K33 -> 14510347 | I33: ='出金明細【17期】'!D32 -> 573237 | J33: ='出金明細【17期】'!M32 -> 11891372 | K33: ='出金明細【17期】'!AD32 -> 2045738
B34: 6月合計 | C34: =SUM(D34-H34) -> -7270002 | D34: =E34+F34+G34 -> 38728869 | E34: =SUM(E4:E33) -> 2506615 | F34: =SUM(F4:F33) -> 170634 | G34: =SUM(G4:G33) -> 36051620 | H34: =SUM(H4:H33) -> 45998871 | I34: =SUM(I4:I33) -> 10804885 | J34: =SUM(J4:J33) -> 25520872 | K34: =SUM(K4:K33) -> 9673114
B35: 累計 | C35: =SUM(D35-H35) -> -7270002 | D35: =E35+F35+G35 -> 38728869 | E35: =E2+E34 -> 2506615 | F35: =F2+F34 -> 170634 | G35: =G2+G34 -> 36051620 | H35: =H2+H34 -> 45998871 | I35: =I2+I34 -> 10804885 | J35: =J2+J34 -> 25520872 | K35: =K2+K34 -> 9673114
B36: 44378 | C36: =SUM(C33+D36-H36) -> 7142107 | D36: =E36+F36+G36 -> 0 | E36: ='入金明細【17期】'!D35 -> 0 | F36: ='入金明細【17期】'!M35 -> 0 | G36: ='入金明細【17期】'!T35 -> 0 | H36: =I36+J36+K36 -> 50611 | I36: ='出金明細【17期】'!D35 -> 0 | J36: ='出金明細【17期】'!M35 -> 0 | K36: ='出金明細【17期】'!AD35 -> 50611
B37: 45109 | C37: =SUM(C36+D37-H37) -> 7564107 | D37: =E37+F37+G37 -> 430000 | E37: ='入金明細【17期】'!D36 -> 0 | F37: ='入金明細【17期】'!M36 -> 0 | G37: ='入金明細【17期】'!T36 -> 430000 | H37: =I37+J37+K37 -> 8000 | I37: ='出金明細【17期】'!D36 -> 8000 | J37: ='出金明細【17期】'!M36 -> 0 | K37: ='出金明細【17期】'!AD36 -> 0
B38: 45110 | C38: =SUM(C37+D38-H38) -> 37276587 | D38: =E38+F38+G38 -> 29712480 | E38: ='入金明細【17期】'!D37 -> 12470891 | F38: ='入金明細【17期】'!M37 -> 0 | G38: ='入金明細【17期】'!T37 -> 17241589 | H38: =I38+J38+K38 -> 0 | I38: ='出金明細【17期】'!D37 -> 0 | J38: ='出金明細【17期】'!M37 -> 0 | K38: ='出金明細【17期】'!AD37 -> 0
B39: 45111 | C39: =SUM(C38+D39-H39) -> 31403757 | D39: =E39+F39+G39 -> 0 | E39: ='入金明細【17期】'!D38 -> 0 | F39: ='入金明細【17期】'!M38 -> 0 | G39: ='入金明細【17期】'!T38 -> 0 | H39: =I39+J39+K39 -> 5872830 | I39: ='出金明細【17期】'!D38 -> 0 | J39: ='出金明細【17期】'!M38 -> 5731590 | K39: ='出金明細【17期】'!AD38 -> 141240
B40: 45112 | C40: =SUM(C39+D40-H40) -> 31403757 | D40: =E40+F40+G40 -> 0 | E40: ='入金明細【17期】'!D39 -> 0 | F40: ='入金明細【17期】'!M39 -> 0 | G40: ='入金明細【17期】'!T39 -> 0 | H40: =I40+J40+K40 -> 0 | I40: ='出金明細【17期】'!D39 -> 0 | J40: ='出金明細【17期】'!M39 -> 0 | K40: ='出金明細【17期】'!AD39 -> 0
B41: 45113 | C41: =SUM(C40+D41-H41) -> 31403757 | D41: =E41+F41+G41 -> 0 | E41: ='入金明細【17期】'!D40 -> 0 | F41: ='入金明細【17期】'!M40 -> 0 | G41: ='入金明細【17期】'!T40 -> 0 | H41: =I41+J41+K41 -> 0 | I41: ='出金明細【17期】'!D40 -> 0 | J41: ='出金明細【17期】'!M40 -> 0 | K41: ='出金明細【17期】'!AD40 -> 0
B42: 45114 | C42: =SUM(C41+D42-H42) -> 31402547 | D42: =E42+F42+G42 -> 0 | E42: ='入金明細【17期】'!D41 -> 0 | F42: ='入金明細【17期】'!M41 -> 0 | G42: ='入金明細【17期】'!T41 -> 0 | H42: =I42+J42+K42 -> 1210 | I42: ='出金明細【17期】'!D41 -> 1210 | J42: ='出金明細【17期】'!M41 -> 0 | K42: ='出金明細【17期】'!AD41 -> 0
B43: 45115 | C43: =SUM(C42+D43-H43) -> 31648771 | D43: =E43+F43+G43 -> 354024 | E43: ='入金明細【17期】'!D42 -> 0 | F43: ='入金明細【17期】'!M42 -> 0 | G43: ='入金明細【17期】'!T42 -> 354024 | H43: =I43+J43+K43 -> 107800 | I43: ='出金明細【17期】'!D42 -> 0 | J43: ='出金明細【17期】'!M42 -> 0 | K43: ='出金明細【17期】'!AD42 -> 107800
B44: 45116 | C44: =SUM(C43+D44-H44) -> 31640961 | D44: =E44+F44+G44 -> 0 | E44: ='入金明細【17期】'!D43 -> 0 | F44: ='入金明細【17期】'!M43 -> 0 | G44: ='入金明細【17期】'!T43 -> 0 | H44: =I44+J44+K44 -> 7810 | I44: ='出金明細【17期】'!D43 -> 7810 | J44: ='出金明細【17期】'!M43 -> 0 | K44: ='出金明細【17期】'!AD43 -> 0
B45: 45117 | C45: =SUM(C44+D45-H45) -> 15556117 | D45: =E45+F45+G45 -> 0 | E45: ='入金明細【17期】'!D44 -> 0 | F45: ='入金明細【17期】'!M44 -> 0 | G45: ='入金明細【17期】'!T44 -> 0 | H45: =I45+J45+K45 -> 16084844 | I45: ='出金明細【17期】'!D44 -> 132155 | J45: ='出金明細【17期】'!M44 -> 0 | K45: ='出金明細【17期】'!AD44 -> 15952689
B46: 45118 | C46: =SUM(C45+D46-H46) -> 22281556 | D46: =E46+F46+G46 -> 6855439 | E46: ='入金明細【17期】'!D45 -> 0 | F46: ='入金明細【17期】'!M45 -> 0 | G46: ='入金明細【17期】'!T45 -> 6855439 | H46: =I46+J46+K46 -> 130000 | I46: ='出金明細【17期】'!D45 -> 0 | J46: ='出金明細【17期】'!M45 -> 0 | K46: ='出金明細【17期】'!AD45 -> 130000
B47: 45119 | C47: =SUM(C46+D47-H47) -> 22281556 | D47: =E47+F47+G47 -> 0 | E47: ='入金明細【17期】'!D46 -> 0 | F47: ='入金明細【17期】'!M46 -> 0 | G47: ='入金明細【17期】'!T46 -> 0 | H47: =I47+J47+K47 -> 0 | I47: ='出金明細【17期】'!D46 -> 0 | J47: ='出金明細【17期】'!M46 -> 0 | K47: ='出金明細【17期】'!AD46 -> 0
B48: 45120 | C48: =SUM(C47+D48-H48) -> 22281556 | D48: =E48+F48+G48 -> 0 | E48: ='入金明細【17期】'!D47 -> 0 | F48: ='入金明細【17期】'!M47 -> 0 | G48: ='入金明細【17期】'!T47 -> 0 | H48: =I48+J48+K48 -> 0 | I48: ='出金明細【17期】'!D47 -> 0 | J48: ='出金明細【17期】'!M47 -> 0 | K48: ='出金明細【17期】'!AD47 -> 0
... B66: 45138 | C66: =SUM(C65+D66-H66) -> 41007661 | D66: =E66+F66+G66 -> 23047517 | E66: ='入金明細【17期】'!D65 -> 0 | F66: ='入金明細【17期】'!M65 -> 0 | G66: ='入金明細【17期】'!T65 -> 23047517 | H66: =I66+J66+K66 -> 7015830 | I66: ='出金明細【17期】'!D65 -> 436295 | J66: ='出金明細【17期】'!M65 -> 2251085 | K66: ='出金明細【17期】'!AD65 -> 4328450
B67: 7月合計 | C67: =SUM(D67-H67) -> 33814943 | D67: =SUM(D36:D66) -> 73090986 | E67: =SUM(E36:E66) -> 12470891 | F67: =SUM(F36:F66) -> 233540 | G67: =SUM(G36:G66) -> 60386555 | H67: =SUM(H36:H66) -> 39276043 | I67: =SUM(I36:I66) -> 6086612 | J67: =SUM(J36:J66) -> 8133375 | K67: =SUM(K36:K66) -> 25056056
B68: 累計 | C68: =SUM(D68-H68) -> 26544941 | D68: =D35+D67 -> 111819855 | E68: =E35+E67 -> 14977506 | F68: =F35+F67 -> 404174 | G68: =G35+G67 -> 96438175 | H68: =H35+H67 -> 85274914 | I68: =I35+I67 -> 16891497 | J68: =J35+J67 -> 33654247 | K68: =K35+K67 -> 34729170
B69: 45139 | C69: =SUM(C66+D69-H69) -> 40645816 | D69: =E69+F69+G69 -> 0 | E69: ='入金明細【17期】'!D68 -> 0 | F69: ='入金明細【17期】'!M68 | G69: ='入金明細【17期】'!T68 -> 0 | H69: =I69+J69+K69 -> 361845 | I69: ='出金明細【17期】'!D68 -> 0 | J69: ='出金明細【17期】'!M68 -> 288395 | K69: ='出金明細【17期】'!AD68 -> 73450
B70: 45140 | C70: =SUM(C69+D70-H70) -> 40645816 | D70: =E70+F70+G70 -> 0 | E70: ='入金明細【17期】'!D69 -> 0 | F70: ='入金明細【17期】'!M69 | G70: ='入金明細【17期】'!T69 -> 0 | H70: =I70+J70+K70 -> 0 | I70: ='出金明細【17期】'!D69 -> 0 | J70: ='出金明細【17期】'!M69 -> 0 | K70: ='出金明細【17期】'!AD69 -> 0
B71: 45141 | C71: =SUM(C70+D71-H71) -> 40645816 | D71: =E71+F71+G71 -> 0 | E71: ='入金明細【17期】'!D70 -> 0 | F71: ='入金明細【17期】'!M70 | G71: ='入金明細【17期】'!T70 -> 0 | H71: =I71+J71+K71 -> 0 | I71: ='出金明細【17期】'!D70 -> 0 | J71: ='出金明細【17期】'!M70 -> 0 | K71: ='出金明細【17期】'!AD70 -> 0
B72: 45142 | C72: =SUM(C71+D72-H72) -> 39771747 | D72: =E72+F72+G72 -> 0 | E72: ='入金明細【17期】'!D71 -> 0 | F72: ='入金明細【17期】'!M71 | G72: ='入金明細【17期】'!T71 -> 0 | H72: =I72+J72+K72 -> 874069 | I72: ='出金明細【17期】'!D71 -> 0 | J72: ='出金明細【17期】'!M71 -> 0 | K72: ='出金明細【17期】'!AD71 -> 874069
B73: 45143 | C73: =SUM(C72+D73-H73) -> 39771747 | D73: =E73+F73+G73 -> 0 | E73: ='入金明細【17期】'!D72 -> 0 | F73: ='入金明細【17期】'!M72 -> 0 | G73: ='入金明細【17期】'!T72 -> 0 | H73: =I73+J73+K73 -> 0 | I73: ='出金明細【17期】'!D72 -> 0 | J73: ='出金明細【17期】'!M72 -> 0 | K73: ='出金明細【17期】'!AD72 -> 0
...

Sheet 入金明細【17期】
C1: ２０２5年６月‐２０２6年５月入金
C2: 入金日次 | D2: 金融小計 | E2: 金融機関関連 | M2: 保険小計 | N2: 保険関連 | T2: お客様小計 | U2: お客様関連
B3: 44348 | C3: =D3+M3+T3 -> 0 | D3: =F3+H3+J3+L3 -> 0 | M3: =O3+Q3+S3 -> 0 | T3: =V3+X3+Z3+AB3+AD3+AF3+AH3+AJ3+AV3+AL3+AN3+AP3+AR3+'入金明細【17期】'!AT3 -> 0
B4: 44349 | C4: =D4+M4+T4 -> 0 | D4: =F4+H4+J4+L4 -> 0 | M4: =O4+Q4+S4 -> 0 | T4: =V4+X4+Z4+AB4+AD4+AF4+AH4+AJ4+AV4+AL4+AN4+AP4+AR4+AT4 -> 0
B5: 45446 | C5: =D5+M5+T5 -> 1930350 | D5: =F5+H5+J5+L5 -> 600000 | E5: 笠信(小口現金分) | F5: 600000 | M5: =O5+Q5+S5 -> 0 | T5: =V5+X5+Z5+AB5+AD5+AF5+AH5+AJ5+AV5+AL5+AN5+AP5+AR5+AT5 -> 1330350 | U5: 映ｸﾗ㈱様ﾐﾓｻﾞ薬局様日産ﾘｰﾌ | V5: 1330350
B6: 44351 | C6: =D6+M6+T6 -> 77000 | D6: =F6+H6+J6+L6 -> 0 | M6: =O6+Q6+S6 -> 0 | T6: =V6+X6+Z6+AB6+AD6+AF6+AH6+AJ6+AV6+AL6+AN6+AP6+AR6+AT6 -> 77000 | U6: あいおいﾆｯｾｲ同和様 | V6: 77000
B7: 44352 | C7: =D7+M7+T7 -> 65780 | D7: =F7+H7+J7+L7 -> 0 | M7: =O7+Q7+S7 -> 0 | T7: =V7+X7+Z7+AB7+AD7+AF7+AH7+AJ7+AV7+AL7+AN7+AP7+AR7+AT7 -> 65780 | U7: おもてちょう不動産㈱様 | V7: 65780
B8: 44353 | C8: =D8+M8+T8 -> 0 | D8: =F8+H8+J8+L8 -> 0 | M8: =O8+Q8+S8 -> 0 | T8: =V8+X8+Z8+AB8+AD8+AF8+AH8+AJ8+AV8+AL8+AN8+AP8+AR8+AT8 -> 0
B9: 44354 | C9: =D9+M9+T9 -> 25000 | D9: =F9+H9+J9+L9 -> 0 | M9: =O9+Q9+S9 -> 0 | T9: =V9+X9+Z9+AB9+AD9+AF9+AH9+AJ9+AV9+AL9+AN9+AP9+AR9+AT9 -> 25000 | U9: 土肥良太郎様 | V9: 25000
B10: 45816 | C10: =D10+M10+T10 -> 0 | D10: =F10+H10+J10+L10 -> 0 | M10: =O10+Q10+S10 -> 0 | T10: =V10+X10+Z10+AB10+AD10+AF10+AH10+AJ10+AV10+AL10+AN10+AP10+AR10+AT10 -> 0
B11: 44356 | C11: =D11+M11+T11 -> 248 | D11: =F11+H11+J11+L11 -> 248 | E11: 調整分 | F11: 248 | M11: =O11+Q11+S11 -> 0 | T11: =V11+X11+Z11+AB11+AD11+AF11+AH11+AJ11+AV11+AL11+AN11+AP11+AR11+AT11 -> 0
B12: 44357 | C12: =D12+M12+T12 -> 0 | D12: =F12+H12+J12+L12 -> 0 | M12: =O12+Q12+S12 -> 0 | T12: =V12+X12+Z12+AB12+AD12+AF12+AH12+AJ12+AV12+AL12+AN12+AP12+AR12+AT12 -> 0
B13: 44358 | C13: =D13+M13+T13 -> 2009574 | D13: =F13+H13+J13+L13 -> 0 | M13: =O13+Q13+S13 -> 0 | T13: =V13+X13+Z13+AB13+AD13+AF13+AH13+AJ13+AV13+AL13+AN13+AP13+AR13+AT13 -> 2009574 | U13: 東京海上日動 | V13: 2009574
B14: 44359 | C14: =D14+M14+T14 -> 0 | D14: =F14+H14+J14+L14 -> 0 | M14: =O14+Q14+S14 -> 0 | T14: =V14+X14+Z14+AB14+AD14+AF14+AH14+AJ14+AV14+AL14+AN14+AP14+AR14+AT14 -> 0
B15: 44360 | C15: =D15+M15+T15 -> 1900000 | D15: =F15+H15+J15+L15 -> 1900000 | E15: 小口現金より広銀本社へ資金移動（幸洋板金入金分） | F15: 1900000 | M15: =O15+Q15+S15 -> 0 | T15: =V15+X15+Z15+AB15+AD15+AF15+AH15+AJ15+AV15+AL15+AN15+AP15+AR15+AT15 -> 0
B16: 44361 | C16: =D16+M16+T16 -> 0 | D16: =F16+H16+J16+L16 -> 0 | M16: =O16+Q16+S16 -> 0 | T16: =V16+X16+Z16+AB16+AD16+AF16+AH16+AJ16+AV16+AL16+AN16+AP16+AR16+AT16 -> 0
B17: 44362 | C17: =D17+M17+T17 -> 0 | D17: =F17+H17+J17+L17 -> 0 | M17: =O17+Q17+S17 -> 0 | T17: =V17+X17+Z17+AB17+AD17+AF17+AH17+AJ17+AV17+AL17+AN17+AP17+AR17+AT17 -> 0
B18: 44363 | C18: =D18+M18+T18 -> 718547 | D18: =F18+H18+J18+L18 -> 0 | M18: =O18+Q18+S18 -> 138826 | N18: 三井住友海上火災保険㈱代理店保険手数料 | O18: 138826 | T18: =V18+X18+Z18+AB18+AD18+AF18+AH18+AJ18+AV18+AL18+AN18+AP18+AR18+AT18 -> 579721 | U18: ｷﾑﾗﾕﾆﾃｨ様 | V18: 42680 | W18: 中銀JCB | X18: 73547 | Y18: 中銀VISA | Z18: 463494
B19: 44364 | C19: =D19+M19+T19 -> 1815128 | D19: =F19+H19+J19+L19 -> 0 | M19: =O19+Q19+S19 -> 31808 | N19: 東京海上日動 代理店保険手数料 | O19: 31808 | T19: =V19+X19+Z19+AB19+AD19+AF19+AH19+AJ19+AV19+AL19+AN19+AP19+AR19+AT19 -> 1783320 | U19: 日新火災海上保険㈱ 安保雅文様 | V19: 1783320
B20: 44365 | C20: =D20+M20+T20 -> 1592 | D20: =F20+H20+J20+L20 -> 1592 | E20: 配当金出資 | F20: 1592 | M20: =O20+Q20+S20 -> 0 | T20: =V20+X20+Z20+AB20+AD20+AF20+AH20+AJ20+AV20+AL20+AN20+AP20+AR20+AT20 -> 0
B21: 44366 | C21: =D21+M21+T21 -> 391080 | D21: =F21+H21+J21+L21 -> 0 | M21: =O21+Q21+S21 -> 0 | T21: =V21+X21+Z21+AB21+AD21+AF21+AH21+AJ21+AV21+AL21+AN21+AP21+AR21+AT21 -> 391080 | U21: 損保ｼﾞｬﾊﾟﾝ | V21: 300000 | W21: 三栄石油㈱ | X21: 91080
B22: 44367 | C22: =D22+M22+T22 -> 0 | D22: =F22+H22+J22+L22 -> 0 | M22: =O22+Q22+S22 -> 0 | T22: =V22+X22+Z22+AB22+AD22+AF22+AH22+AJ22+AV22+AL22+AN22+AP22+AR22+AT22 -> 0
B23: 44368 | C23: =D23+M23+T23 -> 0 | D23: =F23+H23+J23+L23 -> 0 | M23: =O23+Q23+S23 -> 0 | T23: =V23+X23+Z23+AB23+AD23+AF23+AH23+AJ23+AV23+AL23+AN23+AP23+AR23+AT23 -> 0
B24: 44369 | C24: =D24+M24+T24 -> 0 | D24: =F24+H24+J24+L24 -> 0 | M24: =O24+Q24+S24 -> 0 | T24: =V24+X24+Z24+AB24+AD24+AF24+AH24+AJ24+AV24+AL24+AN24+AP24+AR24+AT24 -> 0
B25: 44370 | C25: =D25+M25+T25 -> 204775 | D25: =F25+H25+J25+L25 -> 4775 | E25: 笠信出資配当 | F25: 4775 | M25: =O25+Q25+S25 -> 0 | T25: =V25+X25+Z25+AB25+AD25+AF25+AH25+AJ25+AV25+AL25+AN25+AP25+AR25+AT25 -> 200000 | U25: 藤田勲様 | V25: 200000
B26: 44371 | C26: =D26+M26+T26 -> 3761192 | D26: =F26+H26+J26+L26 -> 0 | M26: =O26+Q26+S26 -> 0 | T26: =V26+X26+Z26+AB26+AD26+AF26+AH26+AJ26+AV26+AL26+AN26+AP26+AR26+AT26 -> 3761192 | U26: 映ｸﾗ㈱様 ﾄﾖﾀ ﾗｲｽﾞ | V26: 1808790 | W26: ㈲ｱﾄﾘｴﾋﾟｭｱ様 | X26: 220000 | Y26: 福山ｽﾎﾟｰﾂ雇用ｻﾎﾟｰﾄｾﾝﾀｰ様 | Z26: 1732402
B27: 44372 | C27: =D27+M27+T27 -> 301970 | D27: =F27+H27+J27+L27 -> 0 | M27: =O27+Q27+S27 -> 0 | T27: =V27+X27+Z27+AB27+AD27+AF27+AH27+AJ27+AV27+AL27+AN27+AP27+AR27+AT27 -> 301970 | U27: 美建工業㈱ | V27: 301970
B28: 44373 | C28: =D28+M28+T28 -> 0 | D28: =F28+H28+J28+L28 -> 0 | M28: =O28+Q28+S28 -> 0 | T28: =V28+X28+Z28+AB28+AD28+AF28+AH28+AJ28+AV28+AL28+AN28+AP28+AR28+AT28 -> 0
B29: 44374 | C29: =D29+M29+T29 -> 9484229 | D29: =F29+H29+J29+L29 -> 0 | M29: =O29+Q29+S29 -> 0 | T29: =V29+X29+Z29+AB29+AD29+AF29+AH29+AJ29+AV29+AL29+AN29+AP29+AR29+AT29 -> 9484229 | U29: ㈱ﾛﾍﾟﾗｲｵ（車両代） | V29: 270809 | W29: ㈱ｽﾋﾟﾝｸﾞﾙｶﾝﾊﾟﾆｰ様 | X29: 9189220 | Y29: ㈱今川建築設計 | Z29: 24200
B30: 44375 | C30: =D30+M30+T30 -> 0 | D30: =F30+H30+J30+L30 -> 0 | M30: =O30+Q30+S30 -> 0 | T30: =V30+X30+Z30+AB30+AD30+AF30+AH30+AJ30+AV30+AL30+AN30+AP30+AR30+AT30 -> 0
B31: 44376 | C31: =D31+M31+T31 -> 0 | D31: =F31+H31+J31+L31 -> 0 | M31: =O31+Q31+S31 -> 0 | T31: =V31+X31+Z31+AB31+AD31+AF31+AH31+AJ31+AV31+AL31+AN31+AP31+AR31+AT31 -> 0
B32: 44377 | C32: =D32+M32+T32 -> 16042404 | D32: =F32+H32+J32+L32 -> 0 | M32: =O32+Q32+S32 -> 0 | T32: =V32+X32+Z32+AB32+AD32+AF32+AH32+AJ32+AV32+AL32+AN32+AP32+AR32+AT32 -> 16042404 | U32: 山道千絵様下取り車自動車税一か月分 | V32: 3000 | W32: ｺﾝｸｴｽﾄ様J&LR営業部門 | X32: 1936707 | Y32: ｺﾝｸｴｽﾄ様J&LR整備 | Z32: 313716 | AA32: ｺﾝｸｴｽﾄ様J&LR営業部門 ﾐﾓｻﾞ薬局様 | AB32: 921030 | AC32: ｺﾝｸｴｽﾄ様ﾗﾝﾄﾞﾛｰﾊﾞｰ小林様分 | AD32: 4557210 | AE32: ｺﾝｸｴｽﾄ様ｼﾞｬｶﾞｰXE林様分 | AF32: 4103046 | AG32: ｺﾝｸｴｽﾄ様紹介料 | AH32: 488164 | AI32: ｺﾝｸｴｽﾄ様経費 | AJ32: 2876175 | AK32: 中銀JCB | AL32: 74292 | AM32: 中銀VISA | AN32: 524526 | AO32: ㈱ｾﾞﾈｺｽ | AP32: 1100 | AQ32: 福山ｽﾎﾟｰﾂ雇用ｻﾎﾟｰﾄｾﾝﾀｰ様 | AR32: 93438 | AS32: あいおいﾆｯｾｲ同和様 | AT32: 150000
B33: ６月合計 | C33: =D33+M33+T33 -> 38728869 | D33: =SUM(D2:D32) -> 2506615 | M33: =SUM(M2:M32) -> 170634 | T33: =SUM(T3:T32) -> 36051620
B34: 未確定 | C34: =D34+M34+T34 -> 0 | T34: =V34+X34+Z34+AB34+AD34+AF34+AH34+AJ34+AV34 -> 0
B35: 44378 | C35: =D35+M35+T35 -> 0 | D35: =F35+H35+J35+L35 -> 0 | M35: =O35+Q35+S35 -> 0 | T35: =V35+X35+Z35+AB35+AD35+AF35+AH35+AJ35+AV35+AL35+AN35+AP35+AR35+AT35 -> 0
B36: 45109 | C36: =D36+M36+T36 -> 430000 | D36: =F36+H36+J36+L36 -> 0 | M36: =O36+Q36+S36 -> 0 | T36: =V36+X36+Z36+AB36+AD36+AF36+AH36+AJ36+AV36+AL36+AN36+AP36+AR36+AT36 -> 430000 | U36: 小畠興産㈱ | V36: 430000
B37: 45110 | C37: =D37+M37+T37 -> 29712480 | D37: =F37+H37+J37+L37 -> 12470891 | E37: 笠信手形貸付金 | F37: 12470891 | M37: =O37+Q37+S37 -> 0 | T37: =V37+X37+Z37+AB37+AD37+AF37+AH37+AJ37+AV37+AL37+AN37+AP37+AR37+AT37 -> 17241589 | U37: 損保ｼﾞｬﾊﾟﾝ | V37: 3656050 | W37: ｽﾄﾛﾝｸﾞﾏｳﾝﾃﾝ様 | X37: 13560539 | Y37: 土肥良太郎様 | Z37: 25000
B38: 45111 | C38: =D38+M38+T38 -> 0 | D38: =F38+H38+J38+L38 -> 0 | M38: =O38+Q38+S38 -> 0 | T38: =V38+X38+Z38+AB38+AD38+AF38+AH38+AJ38+AV38+AL38+AN38+AP38+AR38+AT38 -> 0
B39: 45112 | C39: =D39+M39+T39 -> 0 | D39: =F39+H39+J39+L39 -> 0 | M39: =O39+Q39+S39 -> 0 | T39: =V39+X39+Z39+AB39+AD39+AF39+AH39+AJ39+AV39+AL39+AN39+AP39+AR39+AT39 -> 0
B40: 45113 | C40: =D40+M40+T40 -> 0 | D40: =F40+H40+J40+L40 -> 0 | M40: =O40+Q40+S40 -> 0 | T40: =V40+X40+Z40+AB40+AD40+AF40+AH40+AJ40+AV40+AL40+AN40+AP40+AR40+AT40 -> 0
...

Sheet 出金明細【17期】
C1: ２０２5年６月‐２０２6年５月出金
C2: 出金日次 | D2: 金融小計 | M2: 買掛小計 | AD2: 経費小計
B3: 44348 | C3: =D3+M3+AD3 -> 1732564 | D3: =F3+H3+J3+L3 -> 1732564 | E3: 6/2広銀ｼｮｳｶﾞｼ | F3: 240940 | G3: 6/2もみじ融資利息 | H3: 197624 | I3: 6/2もみじ長期借入返済 | J3: 404000 | K3: 6/2もみじ長期借入返済 | L3: 890000 | M3: =O3+Q3+S3+U3+W3+Y3+AA3+AC3 -> 0 | AD3: =AF3+AH3+AJ3+AL3+AN3+AP3+AR3+AT3+AV3+AX3+AZ3+BB3+BD3+BF3+BH3+BJ3+BL3+BN3+BP3+BR3+BT3+BV3+BX3+BZ3+CB3+CD3 -> 0
B4: 44349 | C4: =D4+M4+AD4 -> 6226157 | D4: =F4+H4+J4+L4 -> 3224600 | E4: 笠信ｼｮｳｶﾞｼ | F4: 522575 | G4: 笠岡貸付利息 | H4: 104041 | I4: 笠信ｼｮｳｶﾞｼ | J4: 2200600 | K4: 笠信ｼｮｳｶﾞｼ397384 | L4: 397384 | M4: =O4+Q4+S4+U4+W4+Y4+AA4+AC4 -> 1043380 | N4: ﾄﾖﾀﾌｧｲﾅﾝｽ残債 ｺﾝｸｴｽﾄ様ｲｳﾞｫｰｸﾞ110362小川様下取り分（映ｸﾗ様より200万円まだ？前田先生提案中 | O4: 1043380 | AD4: =AF4+AH4+AJ4+AL4+AN4+AP4+AR4+AT4+AV4+AX4+AZ4+BB4+BD4+BF4+BH4+BJ4+BL4+BN4+BP4+BR4+BT4+BV4+BX4+BZ4+CB4+CD4 -> 1958177 | AE4: も）ﾄﾖﾀﾌｧｲﾅﾝｽ | AF4: 44411 | AG4: 自動車税 | AH4: 659200 | AI4: 住民税、所得税支払い | AJ4: 78700 | AK4: 笠信）年金事務所 | AL4: 659440 | AM4: ﾋﾞｰﾌｨｰﾙﾄﾞ | AN4: 2200 | AO4: 日本政策公庫 | AP4: 514226
B5: 45446 | C5: =D5+M5+AD5 -> 195360 | D5: =F5+H5+J5+L5 -> 0 | M5: =O5+Q5+S5+U5+W5+Y5+AA5+AC5 -> 0 | AD5: =AF5+AH5+AJ5+AL5+AN5+AP5+AR5+AT5+AV5+AX5+AZ5+BB5+BD5+BF5+BH5+BJ5+BL5+BN5+BP5+BR5+BT5+BV5+BX5+BZ5+CB5+CD5 -> 195360 | AE5: 三井住友FL（SM） | AF5: 195360
B6: 44351 | C6: =D6+M6+AD6 -> 141790 | D6: =F6+H6+J6+L6 -> 550 | E6: 笠信支払手数料 | F6: 550 | M6: =O6+Q6+S6+U6+W6+Y6+AA6+AC6 -> 0 | AD6: =AF6+AH6+AJ6+AL6+AN6+AP6+AR6+AT6+AV6+AX6+AZ6+BB6+BD6+BF6+BH6+BJ6+BL6+BN6+BP6+BR6+BT6+BV6+BX6+BZ6+CB6+CD6 -> 141240 | AE6: 未来経営 | AF6: 88000 | AG6: ﾘｺｰPCﾘｰｽ | AH6: 53240
B7: 44352 | C7: =D7+M7+AD7 -> 0 | D7: =F7+H7+J7+L7 -> 0 | M7: =O7+Q7+S7+U7+W7+Y7+AA7+AC7 -> 0 | AD7: =AF7+AH7+AJ7+AL7+AN7+AP7+AR7+AT7+AV7+AX7+AZ7+BB7+BD7+BF7+BH7+BJ7+BL7+BN7+BP7+BR7+BT7+BV7+BX7+BZ7+CB7+CD7 -> 0 | AE7: 自賠責 | AF7: 0
B8: 44353 | C8: =D8+M8+AD8 -> 0 | D8: =F8+H8+J8+L8 -> 0 | M8: =O8+Q8+S8+U8+W8+Y8+AA8+AC8 -> 0 | AD8: =AF8+AH8+AJ8+AL8+AN8+AP8+AR8+AT8+AV8+AX8+AZ8+BB8+BD8+BF8+BH8+BJ8+BL8+BN8+BP8+BR8+BT8+BV8+BX8+BZ8+CB8+CD8 -> 0
B9: 44354 | C9: =D9+M9+AD9 -> 0 | D9: =F9+H9+J9+L9 -> 0 | M9: =O9+Q9+S9+U9+W9+Y9+AA9+AC9 -> 0 | AD9: =AF9+AH9+AJ9+AL9+AN9+AP9+AR9+AT9+AV9+AX9+AZ9+BB9+BD9+BF9+BH9+BJ9+BL9+BN9+BP9+BR9+BT9+BV9+BX9+BZ9+CB9+CD9 -> 0
B10: 45816 | C10: =D10+M10+AD10 -> 3630 | D10: =F10+H10+J10+L10 -> 3630 | E10: 6/10もみじIB手数料 | F10: 3630 | M10: =O10+Q10+S10+U10+W10+Y10+AA10+AC10 -> 0 | AD10: =AF10+AH10+AJ10+AL10+AN10+AP10+AR10+AT10+AV10+AX10+AZ10+BB10+BD10+BF10+BH10+BJ10+BL10+BN10+BP10+BR10+BT10+BV10+BX10+BZ10+CB10+CD10 -> 0
B11: 44356 | C11: =D11+M11+AD11 -> 14960 | D11: =F11+H11+J11+L11 -> 14960 | E11: 広信支払手数料 | F11: 1210 | G11: 6/10広銀B-WEB基本手数料 | H11: 1650 | I11: 6/10広銀B-WEB伝送基本手数料 | J11: 2530 | K11: 6/10広銀B-WEB振込手数料 | L11: 9570 | M11: =O11+Q11+S11+U11+W11+Y11+AA11+AC11 -> 0 | AD11: =AF11+AH11+AJ11+AL11+AN11+AP11+AR11+AT11+AV11+AX11+AZ11+BB11+BD11+BF11+BH11+BJ11+BL11+BN11+BP11+BR11+BT11+BV11+BX11+BZ11+CB11+CD11 -> 0
B12: 44357 | C12: =D12+M12+AD12 -> 4040944 | D12: =F12+H12+J12+L12 -> 5170 | E12: もみじ残高証明 | F12: 330 | G12: 中銀残高証明 | H12: 330 | I12: 中銀FBｻｰﾋﾞｽ | J12: 3850 | K12: もみじ振込手数料 | L12: 660 | M12: =O12+Q12+S12+U12+W12+Y12+AA12+AC12 -> 0 | AD12: =AF12+AH12+AJ12+AL12+AN12+AP12+AR12+AT12+AV12+AX12+AZ12+BB12+BD12+BF12+BH12+BJ12+BL12+BN12+BP12+BR12+BT12+BV12+BX12+BZ12+CB12+CD12 -> 4035774 | AE12: 田中賢治様 | AF12: 14600 | AG12: 笠信）ｶｰﾄﾞ引落 ﾀﾞｲﾅｰｽﾞ | AH12: 1109555 | AI12: 給与 | AJ12: 1197136 | AK12: 橋本祥子様 | AL12: 700000 | AM12: 高田自動車 | AN12: 259210 | AO12: 銚子さん | AP12: 170000 | AQ12: もみじ引落ｶﾀﾞｲﾅｰｽｶｰﾄﾞ・ﾄﾗｽﾄｸﾗﾌﾞ整備 | AR12: 209532 | AS12: もみじ引落ｶﾀﾞｲﾅｰｽｶｰﾄﾞ・ﾄﾗｽﾄｸﾗﾌﾞ整備 | AT12: 375741
B13: 44358 | C13: =D13+M13+AD13 -> 0 | D13: =F13+H13+J13+L13 -> 0 | M13: =O13+Q13+S13+U13+W13+Y13+AA13+AC13 -> 0 | AD13: =AF13+AH13+AJ13+AL13+AN13+AP13+AR13+AT13+AV13+AX13+AZ13+BB13+BD13+BF13+BH13+BJ13+BL13+BN13+BP13+BR13+BT13+BV13+BX13+BZ13+CB13+CD13 -> 0
B14: 44359 | C14: =D14+M14+AD14 -> 25433 | D14: =F14+H14+J14+L14 -> 0 | M14: =O14+Q14+S14+U14+W14+Y14+AA14+AC14 -> 0 | AD14: =AF14+AH14+AJ14+AL14+AN14+AP14+AR14+AT14+AV14+AX14+AZ14+BB14+BD14+BF14+BH14+BJ14+BL14+BN14+BP14+BR14+BT14+BV14+BX14+BZ14+CB14+CD14 -> 25433 | AE14: ｱｽｸﾙ | AF14: 9628 | AG14: 自賠責 | AH14: 15805
B15: 44360 | C15: =D15+M15+AD15 -> 5000 | D15: =F15+H15+J15+L15 -> 0 | M15: =O15+Q15+S15+U15+W15+Y15+AA15+AC15 -> 0 | AD15: =AF15+AH15+AJ15+AL15+AN15+AP15+AR15+AT15+AV15+AX15+AZ15+BB15+BD15+BF15+BH15+BJ15+BL15+BN15+BP15+BR15+BT15+BV15+BX15+BZ15+CB15+CD15 -> 5000 | AE15: 福山遠鐘ｸﾗﾌﾞ | AF15: 5000
B16: 44361 | C16: =D16+M16+AD16 -> 0 | D16: =F16+H16+J16+L16 -> 0 | M16: =O16+Q16+S16+U16+W16+Y16+AA16+AC16 -> 0 | AD16: =AF16+AH16+AJ16+AL16+AN16+AP16+AR16+AT16+AV16+AX16+AZ16+BB16+BD16+BF16+BH16+BJ16+BL16+BN16+BP16+BR16+BT16+BV16+BX16+BZ16+CB16+CD16 -> 0
B17: 44362 | C17: =D17+M17+AD17 -> 0 | D17: =F17+H17+J17+L17 -> 0 | M17: =O17+Q17+S17+U17+W17+Y17+AA17+AC17 -> 0 | AD17: =AF17+AH17+AJ17+AL17+AN17+AP17+AR17+AT17+AV17+AX17+AZ17+BB17+BD17+BF17+BH17+BJ17+BL17+BN17+BP17+BR17+BT17+BV17+BX17+BZ17+CB17+CD17 -> 0
B18: 44363 | C18: =D18+M18+AD18 -> 0 | D18: =F18+H18+J18+L18 -> 0 | M18: =O18+Q18+S18+U18+W18+Y18+AA18+AC18 -> 0 | AD18: =AF18+AH18+AJ18+AL18+AN18+AP18+AR18+AT18+AV18+AX18+AZ18+BB18+BD18+BF18+BH18+BJ18+BL18+BN18+BP18+BR18+BT18+BV18+BX18+BZ18+CB18+CD18 -> 0
B19: 44364 | C19: =D19+M19+AD19 -> 0 | D19: =F19+H19+J19+L19 -> 0 | M19: =O19+Q19+S19+U19+W19+Y19+AA19+AC19 -> 0 | AD19: =AF19+AH19+AJ19+AL19+AN19+AP19+AR19+AT19+AV19+AX19+AZ19+BB19+BD19+BF19+BH19+BJ19+BL19+BN19+BP19+BR19+BT19+BV19+BX19+BZ19+CB19+CD19 -> 0
B20: 44365 | C20: =D20+M20+AD20 -> 1100 | D20: =F20+H20+J20+L20 -> 1100 | E20: 笠信支払手数料 | F20: 1100 | M20: =O20+Q20+S20+U20+W20+Y20+AA20+AC20 -> 0 | AD20: =AF20+AH20+AJ20+AL20+AN20+AP20+AR20+AT20+AV20+AX20+AZ20+BB20+BD20+BF20+BH20+BJ20+BL20+BN20+BP20+BR20+BT20+BV20+BX20+BZ20+CB20+CD20 -> 0
B21: 44366 | C21: =D21+M21+AD21 -> 1331830 | D21: =F21+H21+J21+L21 -> 0 | M21: =O21+Q21+S21+U21+W21+Y21+AA21+AC21 -> 1300000 | N21: ㈱ｱﾄﾞｸﾞﾗﾌｨｰ様 1,300,000円 | O21: 1300000 | AD21: =AF21+AH21+AJ21+AL21+AN21+AP21+AR21+AT21+AV21+AX21+AZ21+BB21+BD21+BF21+BH21+BJ21+BL21+BN21+BP21+BR21+BT21+BV21+BX21+BZ21+CB21+CD21 -> 31830 | AE21: 自賠責 | AF21: 31830
B22: 44367 | C22: =D22+M22+AD22 -> 56146 | D22: =F22+H22+J22+L22 -> 0 | M22: =O22+Q22+S22+U22+W22+Y22+AA22+AC22 -> 0 | AD22: =AF22+AH22+AJ22+AL22+AN22+AP22+AR22+AT22+AV22+AX22+AZ22+BB22+BD22+BF22+BH22+BJ22+BL22+BN22+BP22+BR22+BT22+BV22+BX22+BZ22+CB22+CD22 -> 56146 | AE22: 三井住友車両保険対人対物17.520円＋販売車車両保険8.894円 | AF22: 25759 | AG22: 本社水道代引落 | AH22: 17247 | AI22: 水道料J&LR | AJ22: 4202 | AK22: 本社水道代引落 | AL22: 3938 | AM22: 希望ﾝﾝﾊﾞｰdyﾏｰｹﾃｨﾝｸﾞ様 | AN22: 5000
B23: 44368 | C23: =D23+M23+AD23 -> 0 | D23: =F23+H23+J23+L23 -> 0 | M23: =O23+Q23+S23+U23+W23+Y23+AA23+AC23 -> 0 | AD23: =AF23+AH23+AJ23+AL23+AN23+AP23+AR23+AT23+AV23+AX23+AZ23+BB23+BD23+BF23+BH23+BJ23+BL23+BN23+BP23+BR23+BT23+BV23+BX23+BZ23+CB23+CD23 -> 0
B24: 44369 | C24: =D24+M24+AD24 -> 0 | D24: =F24+H24+J24+L24 -> 0 | M24: =O24+Q24+S24+U24+W24+Y24+AA24+AC24 -> 0 | AD24: =AF24+AH24+AJ24+AL24+AN24+AP24+AR24+AT24+AV24+AX24+AZ24+BB24+BD24+BF24+BH24+BJ24+BL24+BN24+BP24+BR24+BT24+BV24+BX24+BZ24+CB24+CD24 -> 0
B25: 44370 | C25: =D25+M25+AD25 -> 50918 | D25: =F25+H25+J25+L25 -> 0 | M25: =O25+Q25+S25+U25+W25+Y25+AA25+AC25 -> 0 | AD25: =AF25+AH25+AJ25+AL25+AN25+AP25+AR25+AT25+AV25+AX25+AZ25+BB25+BD25+BF25+BH25+BJ25+BL25+BN25+BP25+BR25+BT25+BV25+BX25+BZ25+CB25+CD25 -> 50918 | AE25: も引落）ｷｬﾉﾝ | AF25: 7918 | AG25: 笠引落）㈱ﾌﾟﾛﾄｺｰﾎﾟﾚｰｼｮﾝ | AH25: 33000 | AI25: 笠信 収入印紙 | AJ25: 10000
B26: 44371 | C26: =D26+M26+AD26 -> 0 | D26: =F26+H26+J26+L26 -> 0 | M26: =O26+Q26+S26+U26+W26+Y26+AA26+AC26 -> 0 | AD26: =AF26+AH26+AJ26+AL26+AN26+AP26+AR26+AT26+AV26+AX26+AZ26+BB26+BD26+BF26+BH26+BJ26+BL26+BN26+BP26+BR26+BT26+BV26+BX26+BZ26+CB26+CD26 -> 0
B27: 44372 | C27: =D27+M27+AD27 -> 220000 | D27: =F27+H27+J27+L27 -> 0 | M27: =O27+Q27+S27+U27+W27+Y27+AA27+AC27 -> 0 | AD27: =AF27+AH27+AJ27+AL27+AN27+AP27+AR27+AT27+AV27+AX27+AZ27+BB27+BD27+BF27+BH27+BJ27+BL27+BN27+BP27+BR27+BT27+BV27+BX27+BZ27+CB27+CD27 -> 220000 | AE27: SoleilﾏｾﾗﾃｨMC20賃貸借2024.9.1～2026.8.31 | AF27: 220000
B28: 44373 | C28: =D28+M28+AD28 -> 542271 | D28: =F28+H28+J28+L28 -> 0 | M28: =O28+Q28+S28+U28+W28+Y28+AA28+AC28 -> 0 | AD28: =AF28+AH28+AJ28+AL28+AN28+AP28+AR28+AT28+AV28+AX28+AZ28+BB28+BD28+BF28+BH28+BJ28+BL28+BN28+BP28+BR28+BT28+BV28+BX28+BZ28+CB28+CD28 -> 542271 | AE28: ｿﾌﾄﾊﾞﾝｸ | AF28: 46680 | AG28: 笠）三井損害保険 | AH28: 172790 | AI28: 自賠責 | AJ28: 31720 | AK28: も）まるとく本社ｺﾋﾟｰ機 | AL28: 2833 | AM28: も）ﾞ引落中国新聞 | AN28: 3900 | AO28: も）ﾕﾆﾏｯﾄ | AP28: 4400 | AQ28: 広島労働局 | AR28: 279948
B29: 44374 | C29: =D29+M29+AD29 -> 11855932 | D29: =F29+H29+J29+L29 -> 204585 | E29: 笠信貸金庫料 | F29: 13200 | G29: 6/30もみじ印紙代 | H29: 6200 | I29: 6/30もみじ融資利息 | J29: 49270 | K29: 6/30もみじ融資利息 | L29: 135915 | M29: =O29+Q29+S29+U29+W29+Y29+AA29+AC29 -> 11286120 | N29: ㈱ｱﾄﾞｸﾞﾗﾌｨｰ様 1,300,000円残り ｽﾋﾟﾝｸﾞﾙｶﾝﾊﾟﾆｰ ﾎﾟﾙｼｪﾏｶﾝ | O29: 11286120 | AD29: =AF29+AH29+AJ29+AL29+AN29+AP29+AR29+AT29+AV29+AX29+AZ29+BB29+BD29+BF29+BH29+BJ29+BL29+BN29+BP29+BR29+BT29+BV29+BX29+BZ29+CB29+CD29 -> 365227 | AE29: 笠信）富士生命 | AF29: 84678 | AG29: も）ﾁｭｰﾘｯﾋ生命 | AH29: 6015 | AI29: も）ｵﾘｺｶｰｻｺﾋﾟｰ機 | AJ29: 27293 | AK29: も）あんしん生命 | AL29: 58201 | AM29: も）三和地所 | AN29: 67440 | AO29: も)ｵﾘｺJCM | AP29: 99000 | AQ29: も）福山法人会 | AR29: 5000 | AS29: 中銀引落)USS月会費 | AT29: 12980 | AU29: も）ｶｰｾﾌﾞﾝﾃﾞｼﾞﾌｨｰﾙﾄﾞｲﾝｽﾏｰﾄｼｽﾃﾑ | AV29: 4620
B30: 44375 | C30: =D30+M30+AD30 -> 1848874 | D30: =F30+H30+J30+L30 -> 1848874 | E30: 6/30笠信現金 | F30: 320135 | G30: 6/30もみじ融資利息 | H30: 234739 | I30: 6/30もみじ長期借入返済 | J30: 404000 | K30: 6/30もみじ長期借入返済 | L30: 890000 | M30: =O30+Q30+S30+U30+W30+Y30+AA30+AC30 -> 0 | AD30: =AF30+AH30+AJ30+AL30+AN30+AP30+AR30+AT30+AV30+AX30+AZ30+BB30+BD30+BF30+BH30+BJ30+BL30+BN30+BP30+BR30+BT30+BV30+BX30+BZ30+CB30+CD30 -> 0
B31: 44376 | C31: =D31+M31+AD31 -> 3195615 | D31: =F31+H31+J31+L31 -> 3195615 | E31: 6/30笠信ｼｮｳｶﾞｼ | F31: 521103 | G31: 6/30笠岡貸付利息 | H31: 100684 | I31: 6/30笠信ｼｮｳｶﾞｼ | J31: 2179160 | K31: 6/30笠信ｼｮｳｶﾞｼ397384 | L31: 394668 | M31: =O31+Q31+S31+U31+W31+Y31+AA31+AC31 -> 0 | AD31: =AF31+AH31+AJ31+AL31+AN31+AP31+AR31+AT31+AV31+AX31+AZ31+BB31+BD31+BF31+BH31+BJ31+BL31+BN31+BP31+BR31+BT31+BV31+BX31+BZ31+CB31+CD31 -> 0
B32: 44377 | C32: =D32+M32+AD32 -> 14510347 | D32: =F32+H32+J32+L32 -> 573237 | E32: ｺﾝｸｴｽﾄ様劣後利息 | F32: 26666 | G32: ｺﾝｸｴｽﾄ様ｸﾞﾚｶｰﾚﾃﾞﾓｶｰ分割 | H32: 305302 | I32: 6/30広銀ｼｮｳｶﾞｼ | J32: 240609 | K32: 中銀振込手数料 | L32: 660 | M32: =O32+Q32+S32+U32+W32+Y32+AA32+AC32 -> 11891372 | N32: ｺﾝｸｴｽﾄJ&LR4月分請求書 | O32: 731588 | P32: ｵﾘｺ地蔵院様ｷﾞﾌﾞﾘ買取 | Q32: 4539820 | R32: ｺﾝｸｴｽﾄ様小川洵様下取り分ﾄﾖﾀﾗｲｽﾞ | S32: 406620 | T32: ﾏｾﾗﾃｨ5月分ｺﾝｸｴｽﾄ様M整備 | U32: 7458 | V32: 月末支払い整備 | W32: 2783176 | X32: ｺﾝｸｴｽﾄ様ｲｳﾞｫｰｸﾞ | Y32: 3422710 | AD32: =AF32+AH32+AJ32+AL32+AN32+AP32+AR32+AT32+AV32+AX32+AZ32+BB32+BD32+BF32+BH32+BJ32+BL32+BN32+BP32+BR32+BT32+BV32+BX32+BZ32+CB32+CD32 -> 2045738 | AE32: 笠）年金事務所 | AF32: 716858 | AG32: ﾋﾞｰﾌｨｰﾙﾄﾞ | AH32: 2200 | AI32: 月末支払 | AJ32: 234044 | AK32: も)日本政策公庫 | AL32: 497636 | AM32: 大和ﾘﾋﾞﾝｸﾞ（但井） | AN32: 65000 | AO32: 吉野ｶﾞﾚｰｼﾞ | AP32: 165000 | AQ32: ウツミ屋証券 | AR32: 160000 | AS32: NPO | AT32: 205000
B33: ６月合計 | C33: =D33+M33+AD33 -> 45998871 | D33: =SUM(D3:D32) -> 10804885 | M33: =SUM(M3:M32) -> 25520872 | AD33: =SUM(AD3:AD32) -> 9673114
B34: 未確定
B35: 44378 | C35: =D35+M35+AD35 -> 50611 | D35: =F35+H35+J35+L35 -> 0 | M35: =O35+Q35+S35+U35+W35+Y35+AA35+AC35 -> 0 | AD35: =AF35+AH35+AJ35+AL35+AN35+AP35+AR35+AT35+AV35+AX35+AZ35+BB35+BD35+BF35+BH35+BJ35+BL35+BN35+BP35+BR35+BT35+BV35+BX35+BZ35+CB35+CD35 -> 50611 | AE35: もみじ）ﾄﾖﾀﾌｧｲﾅﾝｽ | AF35: 50611
B36: 45109 | C36: =D36+M36+AD36 -> 8000 | D36: =F36+H36+J36+L36 -> 8000 | E36: 笠信印紙代現金 | F36: 8000 | M36: =O36+Q36+S36+U36+W36+Y36+AA36+AC36 -> 0 | AD36: =AF36+AH36+AJ36+AL36+AN36+AP36+AR36+AT36+AV36+AX36+AZ36+BB36+BD36+BF36+BH36+BJ36+BL36+BN36+BP36+BR36+BT36+BV36+BX36+BZ36+CB36+CD36 -> 0
B37: 45110 | C37: =D37+M37+AD37 -> 0 | D37: =F37+H37+J37+L37 -> 0 | M37: =O37+Q37+S37+U37+W37+Y37+AA37+AC37 -> 0 | AD37: =AF37+AH37+AJ37+AL37+AN37+AP37+AR37+AT37+AV37+AX37+AZ37+BB37+BD37+BF37+BH37+BJ37+BL37+BN37+BP37+BR37+BT37+BV37+BX37+BZ37+CB37+CD37 -> 0 | AE37: 自賠責 | AF37: 0
B38: 45111 | C38: =D38+M38+AD38 -> 5872830 | D38: =F38+H38+J38+L38 -> 0 | M38: =O38+Q38+S38+U38+W38+Y38+AA38+AC38 -> 5731590 | N38: ｺﾝｸｴｽﾄ様追加BMWﾐﾆ ｼﾞｬｶﾞｰF | O38: 5731590 | AD38: =AF38+AH38+AJ38+AL38+AN38+AP38+AR38+AT38+AV38+AX38+AZ38+BB38+BD38+BF38+BH38+BJ38+BL38+BN38+BP38+BR38+BT38+BV38+BX38+BZ38+CB38+CD38 -> 141240 | AE38: 未来経営 | AF38: 88000 | AG38: ﾘｺｰPCﾘｰｽ | AH38: 53240
B39: 45112 | C39: =D39+M39+AD39 -> 0 | D39: =F39+H39+J39+L39 -> 0 | M39: =O39+Q39+S39+U39+W39+Y39+AA39+AC39 -> 0 | AD39: =AF39+AH39+AJ39+AL39+AN39+AP39+AR39+AT39+AV39+AX39+AZ39+BB39+BD39+BF39+BH39+BJ39+BL39+BN39+BP39+BR39+BT39+BV39+BX39+BZ39+CB39+CD39 -> 0
B40: 45113 | C40: =D40+M40+AD40 -> 0 | D40: =F40+H40+J40+L40 -> 0 | M40: =O40+Q40+S40+U40+W40+Y40+AA40+AC40 -> 0 | AD40: =AF40+AH40+AJ40+AL40+AN40+AP40+AR40+AT40+AV40+AX40+AZ40+BB40+BD40+BF40+BH40+BJ40+BL40+BN40+BP40+BR40+BT40+BV40+BX40+BZ40+CB40+CD40 -> 0
...

Sheet 入出金合計表 【第16期2024年6月～】  
B1: 2024年5月末残 | C1: ='入出金合計表 【第15期2023年6月～】 '!C392 -> 23772071
C2: ２０２4年６月‐２０２5年５月残高
C3: 残高日次 | D3: 入金合計 | E3: 金融機関関連 | F3: 保険関連 | G3: お客様関連 | H3: 出金合計 | I3: 金融機関関連 | J3: 買掛関連 | K3: 経費関連
B4: 44348 | C4: =SUM(C1+D4-H4) -> 23772071 | D4: =E4+F4+G4 -> 0 | E4: ='入金明細 '!D3 -> 0 | F4: ='入金明細 '!M3 | G4: ='入金明細 '!T3 -> 0 | H4: =I4+J4+K4 -> 0 | I4: ='出金明細 '!D3 -> 0 | J4: ='出金明細 '!M3 -> 0 | K4: ='出金明細 '!AD3 -> 0
B5: 44349 | C5: =SUM(C4+D5-H5) -> 23772071 | D5: =E5+F5+G5 -> 0 | E5: ='入金明細 '!D4 -> 0 | F5: ='入金明細 '!M4 | G5: ='入金明細 '!T4 -> 0 | H5: =I5+J5+K5 -> 0 | I5: ='出金明細 '!D4 -> 0 | J5: ='出金明細 '!M4 -> 0 | K5: ='出金明細 '!AD4 -> 0
B6: 45446 | C6: =SUM(C5+D6-H6) -> 23096733 | D6: =E6+F6+G6 -> 258940 | E6: ='入金明細 '!D5 -> 0 | F6: ='入金明細 '!M5 | G6: ='入金明細 '!T5 -> 258940 | H6: =I6+J6+K6 -> 934278 | I6: ='出金明細 '!D5 -> 0 | J6: ='出金明細 '!M5 -> 0 | K6: ='出金明細 '!AD5 -> 934278
B7: 44351 | C7: =SUM(C6+D7-H7) -> 23394341 | D7: =E7+F7+G7 -> 364708 | E7: ='入金明細 '!D6 -> 0 | F7: ='入金明細 '!M6 | G7: ='入金明細 '!T6 -> 364708 | H7: =I7+J7+K7 -> 67100 | I7: ='出金明細 '!D6 -> 0 | J7: ='出金明細 '!M6 -> 0 | K7: ='出金明細 '!AD6 -> 67100
